2021-12-17 23:29:55,459 - ERROR - weibo.py[:1192] - (1064, "You have an error in your SQL syntax; check the manual that corresponds to your MySQL server version for the right syntax to use near '(id)\n                ) ENGINE=InnoDB DEFAULT CHARSET=utf8mb4' at line 13")
Traceback (most recent call last):
  File "E:/PythonProject/weibo-crawler/weibo.py", line 1159, in get_pages
    self.get_user_info()
  File "E:/PythonProject/weibo-crawler/weibo.py", line 281, in get_user_info
    self.user_to_database()
  File "E:/PythonProject/weibo-crawler/weibo.py", line 223, in user_to_database
    self.user_to_mysql()
  File "E:/PythonProject/weibo-crawler/weibo.py", line 215, in user_to_mysql
    self.mysql_create_table(mysql_config, create_table)
  File "E:/PythonProject/weibo-crawler/weibo.py", line 1020, in mysql_create_table
    self.mysql_create(connection, sql)
  File "E:/PythonProject/weibo-crawler/weibo.py", line 991, in mysql_create
    cursor.execute(sql)
  File "C:\Users\Lenovo\AppData\Roaming\Python\Python37\site-packages\pymysql\cursors.py", line 148, in execute
    result = self._query(query)
  File "C:\Users\Lenovo\AppData\Roaming\Python\Python37\site-packages\pymysql\cursors.py", line 310, in _query
    conn.query(q)
  File "C:\Users\Lenovo\AppData\Roaming\Python\Python37\site-packages\pymysql\connections.py", line 548, in query
    self._affected_rows = self._read_query_result(unbuffered=unbuffered)
  File "C:\Users\Lenovo\AppData\Roaming\Python\Python37\site-packages\pymysql\connections.py", line 775, in _read_query_result
    result.read()
  File "C:\Users\Lenovo\AppData\Roaming\Python\Python37\site-packages\pymysql\connections.py", line 1156, in read
    first_packet = self.connection._read_packet()
  File "C:\Users\Lenovo\AppData\Roaming\Python\Python37\site-packages\pymysql\connections.py", line 725, in _read_packet
    packet.raise_for_error()
  File "C:\Users\Lenovo\AppData\Roaming\Python\Python37\site-packages\pymysql\protocol.py", line 221, in raise_for_error
    err.raise_mysql_exception(self._data)
  File "C:\Users\Lenovo\AppData\Roaming\Python\Python37\site-packages\pymysql\err.py", line 143, in raise_mysql_exception
    raise errorclass(errno, errval)
pymysql.err.ProgrammingError: (1064, "You have an error in your SQL syntax; check the manual that corresponds to your MySQL server version for the right syntax to use near '(id)\n                ) ENGINE=InnoDB DEFAULT CHARSET=utf8mb4' at line 13")
2021-12-17 23:29:55,939 - ERROR - weibo.py[:1192] - (1064, "You have an error in your SQL syntax; check the manual that corresponds to your MySQL server version for the right syntax to use near '(id)\n                ) ENGINE=InnoDB DEFAULT CHARSET=utf8mb4' at line 13")
Traceback (most recent call last):
  File "E:/PythonProject/weibo-crawler/weibo.py", line 1159, in get_pages
    self.get_user_info()
  File "E:/PythonProject/weibo-crawler/weibo.py", line 281, in get_user_info
    self.user_to_database()
  File "E:/PythonProject/weibo-crawler/weibo.py", line 223, in user_to_database
    self.user_to_mysql()
  File "E:/PythonProject/weibo-crawler/weibo.py", line 215, in user_to_mysql
    self.mysql_create_table(mysql_config, create_table)
  File "E:/PythonProject/weibo-crawler/weibo.py", line 1020, in mysql_create_table
    self.mysql_create(connection, sql)
  File "E:/PythonProject/weibo-crawler/weibo.py", line 991, in mysql_create
    cursor.execute(sql)
  File "C:\Users\Lenovo\AppData\Roaming\Python\Python37\site-packages\pymysql\cursors.py", line 148, in execute
    result = self._query(query)
  File "C:\Users\Lenovo\AppData\Roaming\Python\Python37\site-packages\pymysql\cursors.py", line 310, in _query
    conn.query(q)
  File "C:\Users\Lenovo\AppData\Roaming\Python\Python37\site-packages\pymysql\connections.py", line 548, in query
    self._affected_rows = self._read_query_result(unbuffered=unbuffered)
  File "C:\Users\Lenovo\AppData\Roaming\Python\Python37\site-packages\pymysql\connections.py", line 775, in _read_query_result
    result.read()
  File "C:\Users\Lenovo\AppData\Roaming\Python\Python37\site-packages\pymysql\connections.py", line 1156, in read
    first_packet = self.connection._read_packet()
  File "C:\Users\Lenovo\AppData\Roaming\Python\Python37\site-packages\pymysql\connections.py", line 725, in _read_packet
    packet.raise_for_error()
  File "C:\Users\Lenovo\AppData\Roaming\Python\Python37\site-packages\pymysql\protocol.py", line 221, in raise_for_error
    err.raise_mysql_exception(self._data)
  File "C:\Users\Lenovo\AppData\Roaming\Python\Python37\site-packages\pymysql\err.py", line 143, in raise_mysql_exception
    raise errorclass(errno, errval)
pymysql.err.ProgrammingError: (1064, "You have an error in your SQL syntax; check the manual that corresponds to your MySQL server version for the right syntax to use near '(id)\n                ) ENGINE=InnoDB DEFAULT CHARSET=utf8mb4' at line 13")
2021-12-17 23:29:56,264 - ERROR - weibo.py[:1192] - (1064, "You have an error in your SQL syntax; check the manual that corresponds to your MySQL server version for the right syntax to use near '(id)\n                ) ENGINE=InnoDB DEFAULT CHARSET=utf8mb4' at line 13")
Traceback (most recent call last):
  File "E:/PythonProject/weibo-crawler/weibo.py", line 1159, in get_pages
    self.get_user_info()
  File "E:/PythonProject/weibo-crawler/weibo.py", line 281, in get_user_info
    self.user_to_database()
  File "E:/PythonProject/weibo-crawler/weibo.py", line 223, in user_to_database
    self.user_to_mysql()
  File "E:/PythonProject/weibo-crawler/weibo.py", line 215, in user_to_mysql
    self.mysql_create_table(mysql_config, create_table)
  File "E:/PythonProject/weibo-crawler/weibo.py", line 1020, in mysql_create_table
    self.mysql_create(connection, sql)
  File "E:/PythonProject/weibo-crawler/weibo.py", line 991, in mysql_create
    cursor.execute(sql)
  File "C:\Users\Lenovo\AppData\Roaming\Python\Python37\site-packages\pymysql\cursors.py", line 148, in execute
    result = self._query(query)
  File "C:\Users\Lenovo\AppData\Roaming\Python\Python37\site-packages\pymysql\cursors.py", line 310, in _query
    conn.query(q)
  File "C:\Users\Lenovo\AppData\Roaming\Python\Python37\site-packages\pymysql\connections.py", line 548, in query
    self._affected_rows = self._read_query_result(unbuffered=unbuffered)
  File "C:\Users\Lenovo\AppData\Roaming\Python\Python37\site-packages\pymysql\connections.py", line 775, in _read_query_result
    result.read()
  File "C:\Users\Lenovo\AppData\Roaming\Python\Python37\site-packages\pymysql\connections.py", line 1156, in read
    first_packet = self.connection._read_packet()
  File "C:\Users\Lenovo\AppData\Roaming\Python\Python37\site-packages\pymysql\connections.py", line 725, in _read_packet
    packet.raise_for_error()
  File "C:\Users\Lenovo\AppData\Roaming\Python\Python37\site-packages\pymysql\protocol.py", line 221, in raise_for_error
    err.raise_mysql_exception(self._data)
  File "C:\Users\Lenovo\AppData\Roaming\Python\Python37\site-packages\pymysql\err.py", line 143, in raise_mysql_exception
    raise errorclass(errno, errval)
pymysql.err.ProgrammingError: (1064, "You have an error in your SQL syntax; check the manual that corresponds to your MySQL server version for the right syntax to use near '(id)\n                ) ENGINE=InnoDB DEFAULT CHARSET=utf8mb4' at line 13")
2021-12-17 23:29:56,579 - ERROR - weibo.py[:1192] - (1064, "You have an error in your SQL syntax; check the manual that corresponds to your MySQL server version for the right syntax to use near '(id)\n                ) ENGINE=InnoDB DEFAULT CHARSET=utf8mb4' at line 13")
Traceback (most recent call last):
  File "E:/PythonProject/weibo-crawler/weibo.py", line 1159, in get_pages
    self.get_user_info()
  File "E:/PythonProject/weibo-crawler/weibo.py", line 281, in get_user_info
    self.user_to_database()
  File "E:/PythonProject/weibo-crawler/weibo.py", line 223, in user_to_database
    self.user_to_mysql()
  File "E:/PythonProject/weibo-crawler/weibo.py", line 215, in user_to_mysql
    self.mysql_create_table(mysql_config, create_table)
  File "E:/PythonProject/weibo-crawler/weibo.py", line 1020, in mysql_create_table
    self.mysql_create(connection, sql)
  File "E:/PythonProject/weibo-crawler/weibo.py", line 991, in mysql_create
    cursor.execute(sql)
  File "C:\Users\Lenovo\AppData\Roaming\Python\Python37\site-packages\pymysql\cursors.py", line 148, in execute
    result = self._query(query)
  File "C:\Users\Lenovo\AppData\Roaming\Python\Python37\site-packages\pymysql\cursors.py", line 310, in _query
    conn.query(q)
  File "C:\Users\Lenovo\AppData\Roaming\Python\Python37\site-packages\pymysql\connections.py", line 548, in query
    self._affected_rows = self._read_query_result(unbuffered=unbuffered)
  File "C:\Users\Lenovo\AppData\Roaming\Python\Python37\site-packages\pymysql\connections.py", line 775, in _read_query_result
    result.read()
  File "C:\Users\Lenovo\AppData\Roaming\Python\Python37\site-packages\pymysql\connections.py", line 1156, in read
    first_packet = self.connection._read_packet()
  File "C:\Users\Lenovo\AppData\Roaming\Python\Python37\site-packages\pymysql\connections.py", line 725, in _read_packet
    packet.raise_for_error()
  File "C:\Users\Lenovo\AppData\Roaming\Python\Python37\site-packages\pymysql\protocol.py", line 221, in raise_for_error
    err.raise_mysql_exception(self._data)
  File "C:\Users\Lenovo\AppData\Roaming\Python\Python37\site-packages\pymysql\err.py", line 143, in raise_mysql_exception
    raise errorclass(errno, errval)
pymysql.err.ProgrammingError: (1064, "You have an error in your SQL syntax; check the manual that corresponds to your MySQL server version for the right syntax to use near '(id)\n                ) ENGINE=InnoDB DEFAULT CHARSET=utf8mb4' at line 13")
2021-12-17 23:29:56,987 - ERROR - weibo.py[:1192] - (1064, "You have an error in your SQL syntax; check the manual that corresponds to your MySQL server version for the right syntax to use near '(id)\n                ) ENGINE=InnoDB DEFAULT CHARSET=utf8mb4' at line 13")
Traceback (most recent call last):
  File "E:/PythonProject/weibo-crawler/weibo.py", line 1159, in get_pages
    self.get_user_info()
  File "E:/PythonProject/weibo-crawler/weibo.py", line 281, in get_user_info
    self.user_to_database()
  File "E:/PythonProject/weibo-crawler/weibo.py", line 223, in user_to_database
    self.user_to_mysql()
  File "E:/PythonProject/weibo-crawler/weibo.py", line 215, in user_to_mysql
    self.mysql_create_table(mysql_config, create_table)
  File "E:/PythonProject/weibo-crawler/weibo.py", line 1020, in mysql_create_table
    self.mysql_create(connection, sql)
  File "E:/PythonProject/weibo-crawler/weibo.py", line 991, in mysql_create
    cursor.execute(sql)
  File "C:\Users\Lenovo\AppData\Roaming\Python\Python37\site-packages\pymysql\cursors.py", line 148, in execute
    result = self._query(query)
  File "C:\Users\Lenovo\AppData\Roaming\Python\Python37\site-packages\pymysql\cursors.py", line 310, in _query
    conn.query(q)
  File "C:\Users\Lenovo\AppData\Roaming\Python\Python37\site-packages\pymysql\connections.py", line 548, in query
    self._affected_rows = self._read_query_result(unbuffered=unbuffered)
  File "C:\Users\Lenovo\AppData\Roaming\Python\Python37\site-packages\pymysql\connections.py", line 775, in _read_query_result
    result.read()
  File "C:\Users\Lenovo\AppData\Roaming\Python\Python37\site-packages\pymysql\connections.py", line 1156, in read
    first_packet = self.connection._read_packet()
  File "C:\Users\Lenovo\AppData\Roaming\Python\Python37\site-packages\pymysql\connections.py", line 725, in _read_packet
    packet.raise_for_error()
  File "C:\Users\Lenovo\AppData\Roaming\Python\Python37\site-packages\pymysql\protocol.py", line 221, in raise_for_error
    err.raise_mysql_exception(self._data)
  File "C:\Users\Lenovo\AppData\Roaming\Python\Python37\site-packages\pymysql\err.py", line 143, in raise_mysql_exception
    raise errorclass(errno, errval)
pymysql.err.ProgrammingError: (1064, "You have an error in your SQL syntax; check the manual that corresponds to your MySQL server version for the right syntax to use near '(id)\n                ) ENGINE=InnoDB DEFAULT CHARSET=utf8mb4' at line 13")
2021-12-17 23:29:57,350 - ERROR - weibo.py[:1192] - (1064, "You have an error in your SQL syntax; check the manual that corresponds to your MySQL server version for the right syntax to use near '(id)\n                ) ENGINE=InnoDB DEFAULT CHARSET=utf8mb4' at line 13")
Traceback (most recent call last):
  File "E:/PythonProject/weibo-crawler/weibo.py", line 1159, in get_pages
    self.get_user_info()
  File "E:/PythonProject/weibo-crawler/weibo.py", line 281, in get_user_info
    self.user_to_database()
  File "E:/PythonProject/weibo-crawler/weibo.py", line 223, in user_to_database
    self.user_to_mysql()
  File "E:/PythonProject/weibo-crawler/weibo.py", line 215, in user_to_mysql
    self.mysql_create_table(mysql_config, create_table)
  File "E:/PythonProject/weibo-crawler/weibo.py", line 1020, in mysql_create_table
    self.mysql_create(connection, sql)
  File "E:/PythonProject/weibo-crawler/weibo.py", line 991, in mysql_create
    cursor.execute(sql)
  File "C:\Users\Lenovo\AppData\Roaming\Python\Python37\site-packages\pymysql\cursors.py", line 148, in execute
    result = self._query(query)
  File "C:\Users\Lenovo\AppData\Roaming\Python\Python37\site-packages\pymysql\cursors.py", line 310, in _query
    conn.query(q)
  File "C:\Users\Lenovo\AppData\Roaming\Python\Python37\site-packages\pymysql\connections.py", line 548, in query
    self._affected_rows = self._read_query_result(unbuffered=unbuffered)
  File "C:\Users\Lenovo\AppData\Roaming\Python\Python37\site-packages\pymysql\connections.py", line 775, in _read_query_result
    result.read()
  File "C:\Users\Lenovo\AppData\Roaming\Python\Python37\site-packages\pymysql\connections.py", line 1156, in read
    first_packet = self.connection._read_packet()
  File "C:\Users\Lenovo\AppData\Roaming\Python\Python37\site-packages\pymysql\connections.py", line 725, in _read_packet
    packet.raise_for_error()
  File "C:\Users\Lenovo\AppData\Roaming\Python\Python37\site-packages\pymysql\protocol.py", line 221, in raise_for_error
    err.raise_mysql_exception(self._data)
  File "C:\Users\Lenovo\AppData\Roaming\Python\Python37\site-packages\pymysql\err.py", line 143, in raise_mysql_exception
    raise errorclass(errno, errval)
pymysql.err.ProgrammingError: (1064, "You have an error in your SQL syntax; check the manual that corresponds to your MySQL server version for the right syntax to use near '(id)\n                ) ENGINE=InnoDB DEFAULT CHARSET=utf8mb4' at line 13")
2021-12-17 23:30:29,761 - ERROR - weibo.py[:1192] - 'since_date'
Traceback (most recent call last):
  File "E:/PythonProject/weibo-crawler/weibo.py", line 1161, in get_pages
    since_date = datetime.strptime(self.user_config['since_date'],
KeyError: 'since_date'
2021-12-17 23:30:30,049 - ERROR - weibo.py[:1192] - 'since_date'
Traceback (most recent call last):
  File "E:/PythonProject/weibo-crawler/weibo.py", line 1161, in get_pages
    since_date = datetime.strptime(self.user_config['since_date'],
KeyError: 'since_date'
2021-12-17 23:30:30,345 - ERROR - weibo.py[:1192] - 'since_date'
Traceback (most recent call last):
  File "E:/PythonProject/weibo-crawler/weibo.py", line 1161, in get_pages
    since_date = datetime.strptime(self.user_config['since_date'],
KeyError: 'since_date'
2021-12-17 23:30:30,684 - ERROR - weibo.py[:1192] - 'since_date'
Traceback (most recent call last):
  File "E:/PythonProject/weibo-crawler/weibo.py", line 1161, in get_pages
    since_date = datetime.strptime(self.user_config['since_date'],
KeyError: 'since_date'
2021-12-17 23:30:31,052 - ERROR - weibo.py[:1192] - 'since_date'
Traceback (most recent call last):
  File "E:/PythonProject/weibo-crawler/weibo.py", line 1161, in get_pages
    since_date = datetime.strptime(self.user_config['since_date'],
KeyError: 'since_date'
2021-12-17 23:30:31,375 - ERROR - weibo.py[:1192] - 'since_date'
Traceback (most recent call last):
  File "E:/PythonProject/weibo-crawler/weibo.py", line 1161, in get_pages
    since_date = datetime.strptime(self.user_config['since_date'],
KeyError: 'since_date'
2021-12-17 23:32:16,311 - ERROR - weibo.py[:684] - can only concatenate str (not "int") to str
Traceback (most recent call last):
  File "E:/PythonProject/weibo-crawler/weibo.py", line 675, in get_one_weibo
    weibo = self.get_long_weibo(weibo_id)
  File "E:/PythonProject/weibo-crawler/weibo.py", line 299, in get_long_weibo
    weibo = self.parse_weibo(weibo_info)
  File "E:/PythonProject/weibo-crawler/weibo.py", line 579, in parse_weibo
    weibo['article_url'] = "https://m.weibo.cn/detail/" + weibo['id']
TypeError: can only concatenate str (not "int") to str
2021-12-17 23:32:16,312 - ERROR - weibo.py[:684] - can only concatenate str (not "int") to str
Traceback (most recent call last):
  File "E:/PythonProject/weibo-crawler/weibo.py", line 679, in get_one_weibo
    weibo = self.parse_weibo(weibo_info)
  File "E:/PythonProject/weibo-crawler/weibo.py", line 579, in parse_weibo
    weibo['article_url'] = "https://m.weibo.cn/detail/" + weibo['id']
TypeError: can only concatenate str (not "int") to str
2021-12-17 23:32:16,313 - ERROR - weibo.py[:684] - can only concatenate str (not "int") to str
Traceback (most recent call last):
  File "E:/PythonProject/weibo-crawler/weibo.py", line 679, in get_one_weibo
    weibo = self.parse_weibo(weibo_info)
  File "E:/PythonProject/weibo-crawler/weibo.py", line 579, in parse_weibo
    weibo['article_url'] = "https://m.weibo.cn/detail/" + weibo['id']
TypeError: can only concatenate str (not "int") to str
2021-12-17 23:32:16,313 - ERROR - weibo.py[:684] - can only concatenate str (not "int") to str
Traceback (most recent call last):
  File "E:/PythonProject/weibo-crawler/weibo.py", line 679, in get_one_weibo
    weibo = self.parse_weibo(weibo_info)
  File "E:/PythonProject/weibo-crawler/weibo.py", line 579, in parse_weibo
    weibo['article_url'] = "https://m.weibo.cn/detail/" + weibo['id']
TypeError: can only concatenate str (not "int") to str
2021-12-17 23:32:16,313 - ERROR - weibo.py[:684] - can only concatenate str (not "int") to str
Traceback (most recent call last):
  File "E:/PythonProject/weibo-crawler/weibo.py", line 679, in get_one_weibo
    weibo = self.parse_weibo(weibo_info)
  File "E:/PythonProject/weibo-crawler/weibo.py", line 579, in parse_weibo
    weibo['article_url'] = "https://m.weibo.cn/detail/" + weibo['id']
TypeError: can only concatenate str (not "int") to str
2021-12-17 23:32:16,313 - ERROR - weibo.py[:684] - can only concatenate str (not "int") to str
Traceback (most recent call last):
  File "E:/PythonProject/weibo-crawler/weibo.py", line 679, in get_one_weibo
    weibo = self.parse_weibo(weibo_info)
  File "E:/PythonProject/weibo-crawler/weibo.py", line 579, in parse_weibo
    weibo['article_url'] = "https://m.weibo.cn/detail/" + weibo['id']
TypeError: can only concatenate str (not "int") to str
2021-12-17 23:32:16,398 - ERROR - weibo.py[:684] - can only concatenate str (not "int") to str
Traceback (most recent call last):
  File "E:/PythonProject/weibo-crawler/weibo.py", line 675, in get_one_weibo
    weibo = self.get_long_weibo(weibo_id)
  File "E:/PythonProject/weibo-crawler/weibo.py", line 299, in get_long_weibo
    weibo = self.parse_weibo(weibo_info)
  File "E:/PythonProject/weibo-crawler/weibo.py", line 579, in parse_weibo
    weibo['article_url'] = "https://m.weibo.cn/detail/" + weibo['id']
TypeError: can only concatenate str (not "int") to str
2021-12-17 23:32:16,473 - ERROR - weibo.py[:684] - can only concatenate str (not "int") to str
Traceback (most recent call last):
  File "E:/PythonProject/weibo-crawler/weibo.py", line 675, in get_one_weibo
    weibo = self.get_long_weibo(weibo_id)
  File "E:/PythonProject/weibo-crawler/weibo.py", line 299, in get_long_weibo
    weibo = self.parse_weibo(weibo_info)
  File "E:/PythonProject/weibo-crawler/weibo.py", line 579, in parse_weibo
    weibo['article_url'] = "https://m.weibo.cn/detail/" + weibo['id']
TypeError: can only concatenate str (not "int") to str
2021-12-17 23:32:16,474 - ERROR - weibo.py[:684] - can only concatenate str (not "int") to str
Traceback (most recent call last):
  File "E:/PythonProject/weibo-crawler/weibo.py", line 679, in get_one_weibo
    weibo = self.parse_weibo(weibo_info)
  File "E:/PythonProject/weibo-crawler/weibo.py", line 579, in parse_weibo
    weibo['article_url'] = "https://m.weibo.cn/detail/" + weibo['id']
TypeError: can only concatenate str (not "int") to str
2021-12-17 23:32:16,651 - ERROR - weibo.py[:684] - can only concatenate str (not "int") to str
Traceback (most recent call last):
  File "E:/PythonProject/weibo-crawler/weibo.py", line 679, in get_one_weibo
    weibo = self.parse_weibo(weibo_info)
  File "E:/PythonProject/weibo-crawler/weibo.py", line 579, in parse_weibo
    weibo['article_url'] = "https://m.weibo.cn/detail/" + weibo['id']
TypeError: can only concatenate str (not "int") to str
2021-12-17 23:32:16,772 - ERROR - weibo.py[:684] - can only concatenate str (not "int") to str
Traceback (most recent call last):
  File "E:/PythonProject/weibo-crawler/weibo.py", line 675, in get_one_weibo
    weibo = self.get_long_weibo(weibo_id)
  File "E:/PythonProject/weibo-crawler/weibo.py", line 299, in get_long_weibo
    weibo = self.parse_weibo(weibo_info)
  File "E:/PythonProject/weibo-crawler/weibo.py", line 579, in parse_weibo
    weibo['article_url'] = "https://m.weibo.cn/detail/" + weibo['id']
TypeError: can only concatenate str (not "int") to str
2021-12-17 23:32:16,772 - ERROR - weibo.py[:684] - can only concatenate str (not "int") to str
Traceback (most recent call last):
  File "E:/PythonProject/weibo-crawler/weibo.py", line 663, in get_one_weibo
    weibo = self.parse_weibo(weibo_info)
  File "E:/PythonProject/weibo-crawler/weibo.py", line 579, in parse_weibo
    weibo['article_url'] = "https://m.weibo.cn/detail/" + weibo['id']
TypeError: can only concatenate str (not "int") to str
2021-12-17 23:32:16,860 - ERROR - weibo.py[:684] - can only concatenate str (not "int") to str
Traceback (most recent call last):
  File "E:/PythonProject/weibo-crawler/weibo.py", line 675, in get_one_weibo
    weibo = self.get_long_weibo(weibo_id)
  File "E:/PythonProject/weibo-crawler/weibo.py", line 299, in get_long_weibo
    weibo = self.parse_weibo(weibo_info)
  File "E:/PythonProject/weibo-crawler/weibo.py", line 579, in parse_weibo
    weibo['article_url'] = "https://m.weibo.cn/detail/" + weibo['id']
TypeError: can only concatenate str (not "int") to str
2021-12-17 23:32:16,860 - ERROR - weibo.py[:684] - can only concatenate str (not "int") to str
Traceback (most recent call last):
  File "E:/PythonProject/weibo-crawler/weibo.py", line 679, in get_one_weibo
    weibo = self.parse_weibo(weibo_info)
  File "E:/PythonProject/weibo-crawler/weibo.py", line 579, in parse_weibo
    weibo['article_url'] = "https://m.weibo.cn/detail/" + weibo['id']
TypeError: can only concatenate str (not "int") to str
2021-12-17 23:32:16,860 - ERROR - weibo.py[:684] - can only concatenate str (not "int") to str
Traceback (most recent call last):
  File "E:/PythonProject/weibo-crawler/weibo.py", line 679, in get_one_weibo
    weibo = self.parse_weibo(weibo_info)
  File "E:/PythonProject/weibo-crawler/weibo.py", line 579, in parse_weibo
    weibo['article_url'] = "https://m.weibo.cn/detail/" + weibo['id']
TypeError: can only concatenate str (not "int") to str
2021-12-17 23:32:16,861 - ERROR - weibo.py[:684] - can only concatenate str (not "int") to str
Traceback (most recent call last):
  File "E:/PythonProject/weibo-crawler/weibo.py", line 679, in get_one_weibo
    weibo = self.parse_weibo(weibo_info)
  File "E:/PythonProject/weibo-crawler/weibo.py", line 579, in parse_weibo
    weibo['article_url'] = "https://m.weibo.cn/detail/" + weibo['id']
TypeError: can only concatenate str (not "int") to str
2021-12-17 23:32:16,964 - ERROR - weibo.py[:684] - can only concatenate str (not "int") to str
Traceback (most recent call last):
  File "E:/PythonProject/weibo-crawler/weibo.py", line 675, in get_one_weibo
    weibo = self.get_long_weibo(weibo_id)
  File "E:/PythonProject/weibo-crawler/weibo.py", line 299, in get_long_weibo
    weibo = self.parse_weibo(weibo_info)
  File "E:/PythonProject/weibo-crawler/weibo.py", line 579, in parse_weibo
    weibo['article_url'] = "https://m.weibo.cn/detail/" + weibo['id']
TypeError: can only concatenate str (not "int") to str
2021-12-17 23:32:16,965 - ERROR - weibo.py[:684] - can only concatenate str (not "int") to str
Traceback (most recent call last):
  File "E:/PythonProject/weibo-crawler/weibo.py", line 679, in get_one_weibo
    weibo = self.parse_weibo(weibo_info)
  File "E:/PythonProject/weibo-crawler/weibo.py", line 579, in parse_weibo
    weibo['article_url'] = "https://m.weibo.cn/detail/" + weibo['id']
TypeError: can only concatenate str (not "int") to str
2021-12-17 23:32:17,082 - ERROR - weibo.py[:684] - can only concatenate str (not "int") to str
Traceback (most recent call last):
  File "E:/PythonProject/weibo-crawler/weibo.py", line 675, in get_one_weibo
    weibo = self.get_long_weibo(weibo_id)
  File "E:/PythonProject/weibo-crawler/weibo.py", line 299, in get_long_weibo
    weibo = self.parse_weibo(weibo_info)
  File "E:/PythonProject/weibo-crawler/weibo.py", line 579, in parse_weibo
    weibo['article_url'] = "https://m.weibo.cn/detail/" + weibo['id']
TypeError: can only concatenate str (not "int") to str
2021-12-17 23:32:25,261 - ERROR - weibo.py[:684] - can only concatenate str (not "int") to str
Traceback (most recent call last):
  File "E:/PythonProject/weibo-crawler/weibo.py", line 679, in get_one_weibo
    weibo = self.parse_weibo(weibo_info)
  File "E:/PythonProject/weibo-crawler/weibo.py", line 579, in parse_weibo
    weibo['article_url'] = "https://m.weibo.cn/detail/" + weibo['id']
TypeError: can only concatenate str (not "int") to str
2021-12-17 23:32:25,261 - ERROR - weibo.py[:684] - can only concatenate str (not "int") to str
Traceback (most recent call last):
  File "E:/PythonProject/weibo-crawler/weibo.py", line 663, in get_one_weibo
    weibo = self.parse_weibo(weibo_info)
  File "E:/PythonProject/weibo-crawler/weibo.py", line 579, in parse_weibo
    weibo['article_url'] = "https://m.weibo.cn/detail/" + weibo['id']
TypeError: can only concatenate str (not "int") to str
2021-12-17 23:32:25,390 - ERROR - weibo.py[:684] - can only concatenate str (not "int") to str
Traceback (most recent call last):
  File "E:/PythonProject/weibo-crawler/weibo.py", line 675, in get_one_weibo
    weibo = self.get_long_weibo(weibo_id)
  File "E:/PythonProject/weibo-crawler/weibo.py", line 299, in get_long_weibo
    weibo = self.parse_weibo(weibo_info)
  File "E:/PythonProject/weibo-crawler/weibo.py", line 579, in parse_weibo
    weibo['article_url'] = "https://m.weibo.cn/detail/" + weibo['id']
TypeError: can only concatenate str (not "int") to str
2021-12-17 23:32:25,391 - ERROR - weibo.py[:684] - can only concatenate str (not "int") to str
Traceback (most recent call last):
  File "E:/PythonProject/weibo-crawler/weibo.py", line 663, in get_one_weibo
    weibo = self.parse_weibo(weibo_info)
  File "E:/PythonProject/weibo-crawler/weibo.py", line 579, in parse_weibo
    weibo['article_url'] = "https://m.weibo.cn/detail/" + weibo['id']
TypeError: can only concatenate str (not "int") to str
2021-12-17 23:32:25,391 - ERROR - weibo.py[:684] - can only concatenate str (not "int") to str
Traceback (most recent call last):
  File "E:/PythonProject/weibo-crawler/weibo.py", line 679, in get_one_weibo
    weibo = self.parse_weibo(weibo_info)
  File "E:/PythonProject/weibo-crawler/weibo.py", line 579, in parse_weibo
    weibo['article_url'] = "https://m.weibo.cn/detail/" + weibo['id']
TypeError: can only concatenate str (not "int") to str
2021-12-17 23:32:25,391 - ERROR - weibo.py[:684] - can only concatenate str (not "int") to str
Traceback (most recent call last):
  File "E:/PythonProject/weibo-crawler/weibo.py", line 679, in get_one_weibo
    weibo = self.parse_weibo(weibo_info)
  File "E:/PythonProject/weibo-crawler/weibo.py", line 579, in parse_weibo
    weibo['article_url'] = "https://m.weibo.cn/detail/" + weibo['id']
TypeError: can only concatenate str (not "int") to str
2021-12-17 23:32:25,392 - ERROR - weibo.py[:684] - can only concatenate str (not "int") to str
Traceback (most recent call last):
  File "E:/PythonProject/weibo-crawler/weibo.py", line 679, in get_one_weibo
    weibo = self.parse_weibo(weibo_info)
  File "E:/PythonProject/weibo-crawler/weibo.py", line 579, in parse_weibo
    weibo['article_url'] = "https://m.weibo.cn/detail/" + weibo['id']
TypeError: can only concatenate str (not "int") to str
2021-12-17 23:32:25,392 - ERROR - weibo.py[:684] - can only concatenate str (not "int") to str
Traceback (most recent call last):
  File "E:/PythonProject/weibo-crawler/weibo.py", line 679, in get_one_weibo
    weibo = self.parse_weibo(weibo_info)
  File "E:/PythonProject/weibo-crawler/weibo.py", line 579, in parse_weibo
    weibo['article_url'] = "https://m.weibo.cn/detail/" + weibo['id']
TypeError: can only concatenate str (not "int") to str
2021-12-17 23:32:25,392 - ERROR - weibo.py[:684] - can only concatenate str (not "int") to str
Traceback (most recent call last):
  File "E:/PythonProject/weibo-crawler/weibo.py", line 679, in get_one_weibo
    weibo = self.parse_weibo(weibo_info)
  File "E:/PythonProject/weibo-crawler/weibo.py", line 579, in parse_weibo
    weibo['article_url'] = "https://m.weibo.cn/detail/" + weibo['id']
TypeError: can only concatenate str (not "int") to str
2021-12-17 23:32:25,831 - ERROR - weibo.py[:684] - can only concatenate str (not "int") to str
Traceback (most recent call last):
  File "E:/PythonProject/weibo-crawler/weibo.py", line 675, in get_one_weibo
    weibo = self.get_long_weibo(weibo_id)
  File "E:/PythonProject/weibo-crawler/weibo.py", line 299, in get_long_weibo
    weibo = self.parse_weibo(weibo_info)
  File "E:/PythonProject/weibo-crawler/weibo.py", line 579, in parse_weibo
    weibo['article_url'] = "https://m.weibo.cn/detail/" + weibo['id']
TypeError: can only concatenate str (not "int") to str
2021-12-17 23:32:36,003 - ERROR - weibo.py[:684] - can only concatenate str (not "int") to str
Traceback (most recent call last):
  File "E:/PythonProject/weibo-crawler/weibo.py", line 663, in get_one_weibo
    weibo = self.parse_weibo(weibo_info)
  File "E:/PythonProject/weibo-crawler/weibo.py", line 579, in parse_weibo
    weibo['article_url'] = "https://m.weibo.cn/detail/" + weibo['id']
TypeError: can only concatenate str (not "int") to str
2021-12-17 23:32:36,004 - ERROR - weibo.py[:684] - can only concatenate str (not "int") to str
Traceback (most recent call last):
  File "E:/PythonProject/weibo-crawler/weibo.py", line 679, in get_one_weibo
    weibo = self.parse_weibo(weibo_info)
  File "E:/PythonProject/weibo-crawler/weibo.py", line 579, in parse_weibo
    weibo['article_url'] = "https://m.weibo.cn/detail/" + weibo['id']
TypeError: can only concatenate str (not "int") to str
2021-12-17 23:32:36,004 - ERROR - weibo.py[:684] - can only concatenate str (not "int") to str
Traceback (most recent call last):
  File "E:/PythonProject/weibo-crawler/weibo.py", line 663, in get_one_weibo
    weibo = self.parse_weibo(weibo_info)
  File "E:/PythonProject/weibo-crawler/weibo.py", line 579, in parse_weibo
    weibo['article_url'] = "https://m.weibo.cn/detail/" + weibo['id']
TypeError: can only concatenate str (not "int") to str
2021-12-17 23:32:36,005 - ERROR - weibo.py[:684] - can only concatenate str (not "int") to str
Traceback (most recent call last):
  File "E:/PythonProject/weibo-crawler/weibo.py", line 663, in get_one_weibo
    weibo = self.parse_weibo(weibo_info)
  File "E:/PythonProject/weibo-crawler/weibo.py", line 579, in parse_weibo
    weibo['article_url'] = "https://m.weibo.cn/detail/" + weibo['id']
TypeError: can only concatenate str (not "int") to str
2021-12-17 23:32:36,005 - ERROR - weibo.py[:684] - can only concatenate str (not "int") to str
Traceback (most recent call last):
  File "E:/PythonProject/weibo-crawler/weibo.py", line 679, in get_one_weibo
    weibo = self.parse_weibo(weibo_info)
  File "E:/PythonProject/weibo-crawler/weibo.py", line 579, in parse_weibo
    weibo['article_url'] = "https://m.weibo.cn/detail/" + weibo['id']
TypeError: can only concatenate str (not "int") to str
2021-12-17 23:32:36,006 - ERROR - weibo.py[:684] - can only concatenate str (not "int") to str
Traceback (most recent call last):
  File "E:/PythonProject/weibo-crawler/weibo.py", line 663, in get_one_weibo
    weibo = self.parse_weibo(weibo_info)
  File "E:/PythonProject/weibo-crawler/weibo.py", line 579, in parse_weibo
    weibo['article_url'] = "https://m.weibo.cn/detail/" + weibo['id']
TypeError: can only concatenate str (not "int") to str
2021-12-17 23:32:36,007 - ERROR - weibo.py[:684] - can only concatenate str (not "int") to str
Traceback (most recent call last):
  File "E:/PythonProject/weibo-crawler/weibo.py", line 679, in get_one_weibo
    weibo = self.parse_weibo(weibo_info)
  File "E:/PythonProject/weibo-crawler/weibo.py", line 579, in parse_weibo
    weibo['article_url'] = "https://m.weibo.cn/detail/" + weibo['id']
TypeError: can only concatenate str (not "int") to str
2021-12-17 23:32:36,007 - ERROR - weibo.py[:684] - can only concatenate str (not "int") to str
Traceback (most recent call last):
  File "E:/PythonProject/weibo-crawler/weibo.py", line 679, in get_one_weibo
    weibo = self.parse_weibo(weibo_info)
  File "E:/PythonProject/weibo-crawler/weibo.py", line 579, in parse_weibo
    weibo['article_url'] = "https://m.weibo.cn/detail/" + weibo['id']
TypeError: can only concatenate str (not "int") to str
2021-12-17 23:32:36,008 - ERROR - weibo.py[:684] - can only concatenate str (not "int") to str
Traceback (most recent call last):
  File "E:/PythonProject/weibo-crawler/weibo.py", line 663, in get_one_weibo
    weibo = self.parse_weibo(weibo_info)
  File "E:/PythonProject/weibo-crawler/weibo.py", line 579, in parse_weibo
    weibo['article_url'] = "https://m.weibo.cn/detail/" + weibo['id']
TypeError: can only concatenate str (not "int") to str
2021-12-17 23:32:36,008 - ERROR - weibo.py[:684] - can only concatenate str (not "int") to str
Traceback (most recent call last):
  File "E:/PythonProject/weibo-crawler/weibo.py", line 663, in get_one_weibo
    weibo = self.parse_weibo(weibo_info)
  File "E:/PythonProject/weibo-crawler/weibo.py", line 579, in parse_weibo
    weibo['article_url'] = "https://m.weibo.cn/detail/" + weibo['id']
TypeError: can only concatenate str (not "int") to str
2021-12-17 23:32:36,708 - ERROR - weibo.py[:684] - can only concatenate str (not "int") to str
Traceback (most recent call last):
  File "E:/PythonProject/weibo-crawler/weibo.py", line 679, in get_one_weibo
    weibo = self.parse_weibo(weibo_info)
  File "E:/PythonProject/weibo-crawler/weibo.py", line 579, in parse_weibo
    weibo['article_url'] = "https://m.weibo.cn/detail/" + weibo['id']
TypeError: can only concatenate str (not "int") to str
2021-12-17 23:32:36,998 - ERROR - weibo.py[:684] - can only concatenate str (not "int") to str
Traceback (most recent call last):
  File "E:/PythonProject/weibo-crawler/weibo.py", line 675, in get_one_weibo
    weibo = self.get_long_weibo(weibo_id)
  File "E:/PythonProject/weibo-crawler/weibo.py", line 299, in get_long_weibo
    weibo = self.parse_weibo(weibo_info)
  File "E:/PythonProject/weibo-crawler/weibo.py", line 579, in parse_weibo
    weibo['article_url'] = "https://m.weibo.cn/detail/" + weibo['id']
TypeError: can only concatenate str (not "int") to str
2021-12-17 23:32:36,998 - ERROR - weibo.py[:684] - can only concatenate str (not "int") to str
Traceback (most recent call last):
  File "E:/PythonProject/weibo-crawler/weibo.py", line 679, in get_one_weibo
    weibo = self.parse_weibo(weibo_info)
  File "E:/PythonProject/weibo-crawler/weibo.py", line 579, in parse_weibo
    weibo['article_url'] = "https://m.weibo.cn/detail/" + weibo['id']
TypeError: can only concatenate str (not "int") to str
2021-12-17 23:32:36,999 - ERROR - weibo.py[:684] - can only concatenate str (not "int") to str
Traceback (most recent call last):
  File "E:/PythonProject/weibo-crawler/weibo.py", line 663, in get_one_weibo
    weibo = self.parse_weibo(weibo_info)
  File "E:/PythonProject/weibo-crawler/weibo.py", line 579, in parse_weibo
    weibo['article_url'] = "https://m.weibo.cn/detail/" + weibo['id']
TypeError: can only concatenate str (not "int") to str
2021-12-17 23:32:36,999 - ERROR - weibo.py[:684] - can only concatenate str (not "int") to str
Traceback (most recent call last):
  File "E:/PythonProject/weibo-crawler/weibo.py", line 679, in get_one_weibo
    weibo = self.parse_weibo(weibo_info)
  File "E:/PythonProject/weibo-crawler/weibo.py", line 579, in parse_weibo
    weibo['article_url'] = "https://m.weibo.cn/detail/" + weibo['id']
TypeError: can only concatenate str (not "int") to str
2021-12-17 23:32:36,999 - ERROR - weibo.py[:684] - can only concatenate str (not "int") to str
Traceback (most recent call last):
  File "E:/PythonProject/weibo-crawler/weibo.py", line 679, in get_one_weibo
    weibo = self.parse_weibo(weibo_info)
  File "E:/PythonProject/weibo-crawler/weibo.py", line 579, in parse_weibo
    weibo['article_url'] = "https://m.weibo.cn/detail/" + weibo['id']
TypeError: can only concatenate str (not "int") to str
2021-12-17 23:32:36,999 - ERROR - weibo.py[:684] - can only concatenate str (not "int") to str
Traceback (most recent call last):
  File "E:/PythonProject/weibo-crawler/weibo.py", line 663, in get_one_weibo
    weibo = self.parse_weibo(weibo_info)
  File "E:/PythonProject/weibo-crawler/weibo.py", line 579, in parse_weibo
    weibo['article_url'] = "https://m.weibo.cn/detail/" + weibo['id']
TypeError: can only concatenate str (not "int") to str
2021-12-17 23:32:37,000 - ERROR - weibo.py[:684] - can only concatenate str (not "int") to str
Traceback (most recent call last):
  File "E:/PythonProject/weibo-crawler/weibo.py", line 663, in get_one_weibo
    weibo = self.parse_weibo(weibo_info)
  File "E:/PythonProject/weibo-crawler/weibo.py", line 579, in parse_weibo
    weibo['article_url'] = "https://m.weibo.cn/detail/" + weibo['id']
TypeError: can only concatenate str (not "int") to str
2021-12-17 23:32:37,096 - ERROR - weibo.py[:684] - can only concatenate str (not "int") to str
Traceback (most recent call last):
  File "E:/PythonProject/weibo-crawler/weibo.py", line 675, in get_one_weibo
    weibo = self.get_long_weibo(weibo_id)
  File "E:/PythonProject/weibo-crawler/weibo.py", line 299, in get_long_weibo
    weibo = self.parse_weibo(weibo_info)
  File "E:/PythonProject/weibo-crawler/weibo.py", line 579, in parse_weibo
    weibo['article_url'] = "https://m.weibo.cn/detail/" + weibo['id']
TypeError: can only concatenate str (not "int") to str
2021-12-17 23:32:37,096 - ERROR - weibo.py[:684] - can only concatenate str (not "int") to str
Traceback (most recent call last):
  File "E:/PythonProject/weibo-crawler/weibo.py", line 679, in get_one_weibo
    weibo = self.parse_weibo(weibo_info)
  File "E:/PythonProject/weibo-crawler/weibo.py", line 579, in parse_weibo
    weibo['article_url'] = "https://m.weibo.cn/detail/" + weibo['id']
TypeError: can only concatenate str (not "int") to str
2021-12-17 23:32:37,259 - ERROR - weibo.py[:684] - can only concatenate str (not "int") to str
Traceback (most recent call last):
  File "E:/PythonProject/weibo-crawler/weibo.py", line 663, in get_one_weibo
    weibo = self.parse_weibo(weibo_info)
  File "E:/PythonProject/weibo-crawler/weibo.py", line 579, in parse_weibo
    weibo['article_url'] = "https://m.weibo.cn/detail/" + weibo['id']
TypeError: can only concatenate str (not "int") to str
2021-12-17 23:32:37,260 - ERROR - weibo.py[:684] - can only concatenate str (not "int") to str
Traceback (most recent call last):
  File "E:/PythonProject/weibo-crawler/weibo.py", line 663, in get_one_weibo
    weibo = self.parse_weibo(weibo_info)
  File "E:/PythonProject/weibo-crawler/weibo.py", line 579, in parse_weibo
    weibo['article_url'] = "https://m.weibo.cn/detail/" + weibo['id']
TypeError: can only concatenate str (not "int") to str
2021-12-17 23:32:37,260 - ERROR - weibo.py[:684] - can only concatenate str (not "int") to str
Traceback (most recent call last):
  File "E:/PythonProject/weibo-crawler/weibo.py", line 679, in get_one_weibo
    weibo = self.parse_weibo(weibo_info)
  File "E:/PythonProject/weibo-crawler/weibo.py", line 579, in parse_weibo
    weibo['article_url'] = "https://m.weibo.cn/detail/" + weibo['id']
TypeError: can only concatenate str (not "int") to str
2021-12-17 23:32:37,260 - ERROR - weibo.py[:684] - can only concatenate str (not "int") to str
Traceback (most recent call last):
  File "E:/PythonProject/weibo-crawler/weibo.py", line 679, in get_one_weibo
    weibo = self.parse_weibo(weibo_info)
  File "E:/PythonProject/weibo-crawler/weibo.py", line 579, in parse_weibo
    weibo['article_url'] = "https://m.weibo.cn/detail/" + weibo['id']
TypeError: can only concatenate str (not "int") to str
2021-12-17 23:32:37,261 - ERROR - weibo.py[:684] - can only concatenate str (not "int") to str
Traceback (most recent call last):
  File "E:/PythonProject/weibo-crawler/weibo.py", line 663, in get_one_weibo
    weibo = self.parse_weibo(weibo_info)
  File "E:/PythonProject/weibo-crawler/weibo.py", line 579, in parse_weibo
    weibo['article_url'] = "https://m.weibo.cn/detail/" + weibo['id']
TypeError: can only concatenate str (not "int") to str
2021-12-17 23:32:38,173 - ERROR - weibo.py[:684] - can only concatenate str (not "int") to str
Traceback (most recent call last):
  File "E:/PythonProject/weibo-crawler/weibo.py", line 679, in get_one_weibo
    weibo = self.parse_weibo(weibo_info)
  File "E:/PythonProject/weibo-crawler/weibo.py", line 579, in parse_weibo
    weibo['article_url'] = "https://m.weibo.cn/detail/" + weibo['id']
TypeError: can only concatenate str (not "int") to str
2021-12-17 23:32:38,173 - ERROR - weibo.py[:684] - can only concatenate str (not "int") to str
Traceback (most recent call last):
  File "E:/PythonProject/weibo-crawler/weibo.py", line 663, in get_one_weibo
    weibo = self.parse_weibo(weibo_info)
  File "E:/PythonProject/weibo-crawler/weibo.py", line 579, in parse_weibo
    weibo['article_url'] = "https://m.weibo.cn/detail/" + weibo['id']
TypeError: can only concatenate str (not "int") to str
2021-12-17 23:32:38,174 - ERROR - weibo.py[:684] - can only concatenate str (not "int") to str
Traceback (most recent call last):
  File "E:/PythonProject/weibo-crawler/weibo.py", line 663, in get_one_weibo
    weibo = self.parse_weibo(weibo_info)
  File "E:/PythonProject/weibo-crawler/weibo.py", line 579, in parse_weibo
    weibo['article_url'] = "https://m.weibo.cn/detail/" + weibo['id']
TypeError: can only concatenate str (not "int") to str
2021-12-17 23:32:38,174 - ERROR - weibo.py[:684] - can only concatenate str (not "int") to str
Traceback (most recent call last):
  File "E:/PythonProject/weibo-crawler/weibo.py", line 679, in get_one_weibo
    weibo = self.parse_weibo(weibo_info)
  File "E:/PythonProject/weibo-crawler/weibo.py", line 579, in parse_weibo
    weibo['article_url'] = "https://m.weibo.cn/detail/" + weibo['id']
TypeError: can only concatenate str (not "int") to str
2021-12-17 23:32:38,174 - ERROR - weibo.py[:684] - can only concatenate str (not "int") to str
Traceback (most recent call last):
  File "E:/PythonProject/weibo-crawler/weibo.py", line 663, in get_one_weibo
    weibo = self.parse_weibo(weibo_info)
  File "E:/PythonProject/weibo-crawler/weibo.py", line 579, in parse_weibo
    weibo['article_url'] = "https://m.weibo.cn/detail/" + weibo['id']
TypeError: can only concatenate str (not "int") to str
2021-12-17 23:32:38,175 - ERROR - weibo.py[:684] - can only concatenate str (not "int") to str
Traceback (most recent call last):
  File "E:/PythonProject/weibo-crawler/weibo.py", line 663, in get_one_weibo
    weibo = self.parse_weibo(weibo_info)
  File "E:/PythonProject/weibo-crawler/weibo.py", line 579, in parse_weibo
    weibo['article_url'] = "https://m.weibo.cn/detail/" + weibo['id']
TypeError: can only concatenate str (not "int") to str
2021-12-17 23:32:38,175 - ERROR - weibo.py[:684] - can only concatenate str (not "int") to str
Traceback (most recent call last):
  File "E:/PythonProject/weibo-crawler/weibo.py", line 663, in get_one_weibo
    weibo = self.parse_weibo(weibo_info)
  File "E:/PythonProject/weibo-crawler/weibo.py", line 579, in parse_weibo
    weibo['article_url'] = "https://m.weibo.cn/detail/" + weibo['id']
TypeError: can only concatenate str (not "int") to str
2021-12-17 23:32:38,175 - ERROR - weibo.py[:684] - can only concatenate str (not "int") to str
Traceback (most recent call last):
  File "E:/PythonProject/weibo-crawler/weibo.py", line 663, in get_one_weibo
    weibo = self.parse_weibo(weibo_info)
  File "E:/PythonProject/weibo-crawler/weibo.py", line 579, in parse_weibo
    weibo['article_url'] = "https://m.weibo.cn/detail/" + weibo['id']
TypeError: can only concatenate str (not "int") to str
2021-12-17 23:32:38,175 - ERROR - weibo.py[:684] - can only concatenate str (not "int") to str
Traceback (most recent call last):
  File "E:/PythonProject/weibo-crawler/weibo.py", line 663, in get_one_weibo
    weibo = self.parse_weibo(weibo_info)
  File "E:/PythonProject/weibo-crawler/weibo.py", line 579, in parse_weibo
    weibo['article_url'] = "https://m.weibo.cn/detail/" + weibo['id']
TypeError: can only concatenate str (not "int") to str
2021-12-17 23:32:38,175 - ERROR - weibo.py[:684] - can only concatenate str (not "int") to str
Traceback (most recent call last):
  File "E:/PythonProject/weibo-crawler/weibo.py", line 663, in get_one_weibo
    weibo = self.parse_weibo(weibo_info)
  File "E:/PythonProject/weibo-crawler/weibo.py", line 579, in parse_weibo
    weibo['article_url'] = "https://m.weibo.cn/detail/" + weibo['id']
TypeError: can only concatenate str (not "int") to str
2021-12-17 23:32:38,176 - ERROR - weibo.py[:684] - can only concatenate str (not "int") to str
Traceback (most recent call last):
  File "E:/PythonProject/weibo-crawler/weibo.py", line 663, in get_one_weibo
    weibo = self.parse_weibo(weibo_info)
  File "E:/PythonProject/weibo-crawler/weibo.py", line 579, in parse_weibo
    weibo['article_url'] = "https://m.weibo.cn/detail/" + weibo['id']
TypeError: can only concatenate str (not "int") to str
2021-12-17 23:32:44,390 - ERROR - weibo.py[:684] - can only concatenate str (not "int") to str
Traceback (most recent call last):
  File "E:/PythonProject/weibo-crawler/weibo.py", line 663, in get_one_weibo
    weibo = self.parse_weibo(weibo_info)
  File "E:/PythonProject/weibo-crawler/weibo.py", line 579, in parse_weibo
    weibo['article_url'] = "https://m.weibo.cn/detail/" + weibo['id']
TypeError: can only concatenate str (not "int") to str
2021-12-17 23:32:44,390 - ERROR - weibo.py[:684] - can only concatenate str (not "int") to str
Traceback (most recent call last):
  File "E:/PythonProject/weibo-crawler/weibo.py", line 663, in get_one_weibo
    weibo = self.parse_weibo(weibo_info)
  File "E:/PythonProject/weibo-crawler/weibo.py", line 579, in parse_weibo
    weibo['article_url'] = "https://m.weibo.cn/detail/" + weibo['id']
TypeError: can only concatenate str (not "int") to str
2021-12-17 23:32:44,390 - ERROR - weibo.py[:684] - can only concatenate str (not "int") to str
Traceback (most recent call last):
  File "E:/PythonProject/weibo-crawler/weibo.py", line 663, in get_one_weibo
    weibo = self.parse_weibo(weibo_info)
  File "E:/PythonProject/weibo-crawler/weibo.py", line 579, in parse_weibo
    weibo['article_url'] = "https://m.weibo.cn/detail/" + weibo['id']
TypeError: can only concatenate str (not "int") to str
2021-12-17 23:32:44,391 - ERROR - weibo.py[:684] - can only concatenate str (not "int") to str
Traceback (most recent call last):
  File "E:/PythonProject/weibo-crawler/weibo.py", line 663, in get_one_weibo
    weibo = self.parse_weibo(weibo_info)
  File "E:/PythonProject/weibo-crawler/weibo.py", line 579, in parse_weibo
    weibo['article_url'] = "https://m.weibo.cn/detail/" + weibo['id']
TypeError: can only concatenate str (not "int") to str
2021-12-17 23:32:44,391 - ERROR - weibo.py[:684] - can only concatenate str (not "int") to str
Traceback (most recent call last):
  File "E:/PythonProject/weibo-crawler/weibo.py", line 663, in get_one_weibo
    weibo = self.parse_weibo(weibo_info)
  File "E:/PythonProject/weibo-crawler/weibo.py", line 579, in parse_weibo
    weibo['article_url'] = "https://m.weibo.cn/detail/" + weibo['id']
TypeError: can only concatenate str (not "int") to str
2021-12-17 23:32:44,475 - ERROR - weibo.py[:684] - can only concatenate str (not "int") to str
Traceback (most recent call last):
  File "E:/PythonProject/weibo-crawler/weibo.py", line 675, in get_one_weibo
    weibo = self.get_long_weibo(weibo_id)
  File "E:/PythonProject/weibo-crawler/weibo.py", line 299, in get_long_weibo
    weibo = self.parse_weibo(weibo_info)
  File "E:/PythonProject/weibo-crawler/weibo.py", line 579, in parse_weibo
    weibo['article_url'] = "https://m.weibo.cn/detail/" + weibo['id']
TypeError: can only concatenate str (not "int") to str
2021-12-17 23:32:44,476 - ERROR - weibo.py[:684] - can only concatenate str (not "int") to str
Traceback (most recent call last):
  File "E:/PythonProject/weibo-crawler/weibo.py", line 679, in get_one_weibo
    weibo = self.parse_weibo(weibo_info)
  File "E:/PythonProject/weibo-crawler/weibo.py", line 579, in parse_weibo
    weibo['article_url'] = "https://m.weibo.cn/detail/" + weibo['id']
TypeError: can only concatenate str (not "int") to str
2021-12-17 23:32:44,476 - ERROR - weibo.py[:684] - can only concatenate str (not "int") to str
Traceback (most recent call last):
  File "E:/PythonProject/weibo-crawler/weibo.py", line 679, in get_one_weibo
    weibo = self.parse_weibo(weibo_info)
  File "E:/PythonProject/weibo-crawler/weibo.py", line 579, in parse_weibo
    weibo['article_url'] = "https://m.weibo.cn/detail/" + weibo['id']
TypeError: can only concatenate str (not "int") to str
2021-12-17 23:32:44,476 - ERROR - weibo.py[:684] - can only concatenate str (not "int") to str
Traceback (most recent call last):
  File "E:/PythonProject/weibo-crawler/weibo.py", line 679, in get_one_weibo
    weibo = self.parse_weibo(weibo_info)
  File "E:/PythonProject/weibo-crawler/weibo.py", line 579, in parse_weibo
    weibo['article_url'] = "https://m.weibo.cn/detail/" + weibo['id']
TypeError: can only concatenate str (not "int") to str
2021-12-17 23:32:44,569 - ERROR - weibo.py[:684] - can only concatenate str (not "int") to str
Traceback (most recent call last):
  File "E:/PythonProject/weibo-crawler/weibo.py", line 675, in get_one_weibo
    weibo = self.get_long_weibo(weibo_id)
  File "E:/PythonProject/weibo-crawler/weibo.py", line 299, in get_long_weibo
    weibo = self.parse_weibo(weibo_info)
  File "E:/PythonProject/weibo-crawler/weibo.py", line 579, in parse_weibo
    weibo['article_url'] = "https://m.weibo.cn/detail/" + weibo['id']
TypeError: can only concatenate str (not "int") to str
2021-12-17 23:32:44,961 - ERROR - weibo.py[:684] - can only concatenate str (not "int") to str
Traceback (most recent call last):
  File "E:/PythonProject/weibo-crawler/weibo.py", line 663, in get_one_weibo
    weibo = self.parse_weibo(weibo_info)
  File "E:/PythonProject/weibo-crawler/weibo.py", line 579, in parse_weibo
    weibo['article_url'] = "https://m.weibo.cn/detail/" + weibo['id']
TypeError: can only concatenate str (not "int") to str
2021-12-17 23:32:44,962 - ERROR - weibo.py[:684] - can only concatenate str (not "int") to str
Traceback (most recent call last):
  File "E:/PythonProject/weibo-crawler/weibo.py", line 663, in get_one_weibo
    weibo = self.parse_weibo(weibo_info)
  File "E:/PythonProject/weibo-crawler/weibo.py", line 579, in parse_weibo
    weibo['article_url'] = "https://m.weibo.cn/detail/" + weibo['id']
TypeError: can only concatenate str (not "int") to str
2021-12-17 23:32:45,087 - ERROR - weibo.py[:684] - can only concatenate str (not "int") to str
Traceback (most recent call last):
  File "E:/PythonProject/weibo-crawler/weibo.py", line 675, in get_one_weibo
    weibo = self.get_long_weibo(weibo_id)
  File "E:/PythonProject/weibo-crawler/weibo.py", line 299, in get_long_weibo
    weibo = self.parse_weibo(weibo_info)
  File "E:/PythonProject/weibo-crawler/weibo.py", line 579, in parse_weibo
    weibo['article_url'] = "https://m.weibo.cn/detail/" + weibo['id']
TypeError: can only concatenate str (not "int") to str
2021-12-17 23:32:45,087 - ERROR - weibo.py[:684] - can only concatenate str (not "int") to str
Traceback (most recent call last):
  File "E:/PythonProject/weibo-crawler/weibo.py", line 663, in get_one_weibo
    weibo = self.parse_weibo(weibo_info)
  File "E:/PythonProject/weibo-crawler/weibo.py", line 579, in parse_weibo
    weibo['article_url'] = "https://m.weibo.cn/detail/" + weibo['id']
TypeError: can only concatenate str (not "int") to str
2021-12-17 23:32:45,088 - ERROR - weibo.py[:684] - can only concatenate str (not "int") to str
Traceback (most recent call last):
  File "E:/PythonProject/weibo-crawler/weibo.py", line 663, in get_one_weibo
    weibo = self.parse_weibo(weibo_info)
  File "E:/PythonProject/weibo-crawler/weibo.py", line 579, in parse_weibo
    weibo['article_url'] = "https://m.weibo.cn/detail/" + weibo['id']
TypeError: can only concatenate str (not "int") to str
2021-12-17 23:32:45,088 - ERROR - weibo.py[:684] - can only concatenate str (not "int") to str
Traceback (most recent call last):
  File "E:/PythonProject/weibo-crawler/weibo.py", line 663, in get_one_weibo
    weibo = self.parse_weibo(weibo_info)
  File "E:/PythonProject/weibo-crawler/weibo.py", line 579, in parse_weibo
    weibo['article_url'] = "https://m.weibo.cn/detail/" + weibo['id']
TypeError: can only concatenate str (not "int") to str
2021-12-17 23:32:45,088 - ERROR - weibo.py[:684] - can only concatenate str (not "int") to str
Traceback (most recent call last):
  File "E:/PythonProject/weibo-crawler/weibo.py", line 663, in get_one_weibo
    weibo = self.parse_weibo(weibo_info)
  File "E:/PythonProject/weibo-crawler/weibo.py", line 579, in parse_weibo
    weibo['article_url'] = "https://m.weibo.cn/detail/" + weibo['id']
TypeError: can only concatenate str (not "int") to str
2021-12-17 23:32:45,089 - ERROR - weibo.py[:684] - can only concatenate str (not "int") to str
Traceback (most recent call last):
  File "E:/PythonProject/weibo-crawler/weibo.py", line 663, in get_one_weibo
    weibo = self.parse_weibo(weibo_info)
  File "E:/PythonProject/weibo-crawler/weibo.py", line 579, in parse_weibo
    weibo['article_url'] = "https://m.weibo.cn/detail/" + weibo['id']
TypeError: can only concatenate str (not "int") to str
2021-12-17 23:32:45,089 - ERROR - weibo.py[:684] - can only concatenate str (not "int") to str
Traceback (most recent call last):
  File "E:/PythonProject/weibo-crawler/weibo.py", line 679, in get_one_weibo
    weibo = self.parse_weibo(weibo_info)
  File "E:/PythonProject/weibo-crawler/weibo.py", line 579, in parse_weibo
    weibo['article_url'] = "https://m.weibo.cn/detail/" + weibo['id']
TypeError: can only concatenate str (not "int") to str
2021-12-17 23:32:45,089 - ERROR - weibo.py[:684] - can only concatenate str (not "int") to str
Traceback (most recent call last):
  File "E:/PythonProject/weibo-crawler/weibo.py", line 663, in get_one_weibo
    weibo = self.parse_weibo(weibo_info)
  File "E:/PythonProject/weibo-crawler/weibo.py", line 579, in parse_weibo
    weibo['article_url'] = "https://m.weibo.cn/detail/" + weibo['id']
TypeError: can only concatenate str (not "int") to str
2021-12-17 23:52:58,934 - ERROR - weibo.py[:1049] - (1054, "Unknown column 'verified_type' in 'field list'")
Traceback (most recent call last):
  File "E:/PythonProject/weibo-crawler/weibo.py", line 1045, in mysql_insert
    sql, [tuple(data.values()) for data in data_list])
  File "C:\Users\Lenovo\AppData\Roaming\Python\Python37\site-packages\pymysql\cursors.py", line 182, in executemany
    self.rowcount = sum(self.execute(query, arg) for arg in args)
  File "C:\Users\Lenovo\AppData\Roaming\Python\Python37\site-packages\pymysql\cursors.py", line 182, in <genexpr>
    self.rowcount = sum(self.execute(query, arg) for arg in args)
  File "C:\Users\Lenovo\AppData\Roaming\Python\Python37\site-packages\pymysql\cursors.py", line 148, in execute
    result = self._query(query)
  File "C:\Users\Lenovo\AppData\Roaming\Python\Python37\site-packages\pymysql\cursors.py", line 310, in _query
    conn.query(q)
  File "C:\Users\Lenovo\AppData\Roaming\Python\Python37\site-packages\pymysql\connections.py", line 548, in query
    self._affected_rows = self._read_query_result(unbuffered=unbuffered)
  File "C:\Users\Lenovo\AppData\Roaming\Python\Python37\site-packages\pymysql\connections.py", line 775, in _read_query_result
    result.read()
  File "C:\Users\Lenovo\AppData\Roaming\Python\Python37\site-packages\pymysql\connections.py", line 1156, in read
    first_packet = self.connection._read_packet()
  File "C:\Users\Lenovo\AppData\Roaming\Python\Python37\site-packages\pymysql\connections.py", line 725, in _read_packet
    packet.raise_for_error()
  File "C:\Users\Lenovo\AppData\Roaming\Python\Python37\site-packages\pymysql\protocol.py", line 221, in raise_for_error
    err.raise_mysql_exception(self._data)
  File "C:\Users\Lenovo\AppData\Roaming\Python\Python37\site-packages\pymysql\err.py", line 143, in raise_mysql_exception
    raise errorclass(errno, errval)
pymysql.err.OperationalError: (1054, "Unknown column 'verified_type' in 'field list'")
2021-12-17 23:52:59,636 - ERROR - weibo.py[:1049] - (1054, "Unknown column 'verified_type' in 'field list'")
Traceback (most recent call last):
  File "E:/PythonProject/weibo-crawler/weibo.py", line 1045, in mysql_insert
    sql, [tuple(data.values()) for data in data_list])
  File "C:\Users\Lenovo\AppData\Roaming\Python\Python37\site-packages\pymysql\cursors.py", line 182, in executemany
    self.rowcount = sum(self.execute(query, arg) for arg in args)
  File "C:\Users\Lenovo\AppData\Roaming\Python\Python37\site-packages\pymysql\cursors.py", line 182, in <genexpr>
    self.rowcount = sum(self.execute(query, arg) for arg in args)
  File "C:\Users\Lenovo\AppData\Roaming\Python\Python37\site-packages\pymysql\cursors.py", line 148, in execute
    result = self._query(query)
  File "C:\Users\Lenovo\AppData\Roaming\Python\Python37\site-packages\pymysql\cursors.py", line 310, in _query
    conn.query(q)
  File "C:\Users\Lenovo\AppData\Roaming\Python\Python37\site-packages\pymysql\connections.py", line 548, in query
    self._affected_rows = self._read_query_result(unbuffered=unbuffered)
  File "C:\Users\Lenovo\AppData\Roaming\Python\Python37\site-packages\pymysql\connections.py", line 775, in _read_query_result
    result.read()
  File "C:\Users\Lenovo\AppData\Roaming\Python\Python37\site-packages\pymysql\connections.py", line 1156, in read
    first_packet = self.connection._read_packet()
  File "C:\Users\Lenovo\AppData\Roaming\Python\Python37\site-packages\pymysql\connections.py", line 725, in _read_packet
    packet.raise_for_error()
  File "C:\Users\Lenovo\AppData\Roaming\Python\Python37\site-packages\pymysql\protocol.py", line 221, in raise_for_error
    err.raise_mysql_exception(self._data)
  File "C:\Users\Lenovo\AppData\Roaming\Python\Python37\site-packages\pymysql\err.py", line 143, in raise_mysql_exception
    raise errorclass(errno, errval)
pymysql.err.OperationalError: (1054, "Unknown column 'verified_type' in 'field list'")
2021-12-17 23:53:01,894 - ERROR - weibo.py[:1049] - (1054, "Unknown column 'verified_type' in 'field list'")
Traceback (most recent call last):
  File "E:/PythonProject/weibo-crawler/weibo.py", line 1045, in mysql_insert
    sql, [tuple(data.values()) for data in data_list])
  File "C:\Users\Lenovo\AppData\Roaming\Python\Python37\site-packages\pymysql\cursors.py", line 182, in executemany
    self.rowcount = sum(self.execute(query, arg) for arg in args)
  File "C:\Users\Lenovo\AppData\Roaming\Python\Python37\site-packages\pymysql\cursors.py", line 182, in <genexpr>
    self.rowcount = sum(self.execute(query, arg) for arg in args)
  File "C:\Users\Lenovo\AppData\Roaming\Python\Python37\site-packages\pymysql\cursors.py", line 148, in execute
    result = self._query(query)
  File "C:\Users\Lenovo\AppData\Roaming\Python\Python37\site-packages\pymysql\cursors.py", line 310, in _query
    conn.query(q)
  File "C:\Users\Lenovo\AppData\Roaming\Python\Python37\site-packages\pymysql\connections.py", line 548, in query
    self._affected_rows = self._read_query_result(unbuffered=unbuffered)
  File "C:\Users\Lenovo\AppData\Roaming\Python\Python37\site-packages\pymysql\connections.py", line 775, in _read_query_result
    result.read()
  File "C:\Users\Lenovo\AppData\Roaming\Python\Python37\site-packages\pymysql\connections.py", line 1156, in read
    first_packet = self.connection._read_packet()
  File "C:\Users\Lenovo\AppData\Roaming\Python\Python37\site-packages\pymysql\connections.py", line 725, in _read_packet
    packet.raise_for_error()
  File "C:\Users\Lenovo\AppData\Roaming\Python\Python37\site-packages\pymysql\protocol.py", line 221, in raise_for_error
    err.raise_mysql_exception(self._data)
  File "C:\Users\Lenovo\AppData\Roaming\Python\Python37\site-packages\pymysql\err.py", line 143, in raise_mysql_exception
    raise errorclass(errno, errval)
pymysql.err.OperationalError: (1054, "Unknown column 'verified_type' in 'field list'")
2021-12-17 23:53:02,717 - ERROR - weibo.py[:1049] - (1054, "Unknown column 'verified_type' in 'field list'")
Traceback (most recent call last):
  File "E:/PythonProject/weibo-crawler/weibo.py", line 1045, in mysql_insert
    sql, [tuple(data.values()) for data in data_list])
  File "C:\Users\Lenovo\AppData\Roaming\Python\Python37\site-packages\pymysql\cursors.py", line 182, in executemany
    self.rowcount = sum(self.execute(query, arg) for arg in args)
  File "C:\Users\Lenovo\AppData\Roaming\Python\Python37\site-packages\pymysql\cursors.py", line 182, in <genexpr>
    self.rowcount = sum(self.execute(query, arg) for arg in args)
  File "C:\Users\Lenovo\AppData\Roaming\Python\Python37\site-packages\pymysql\cursors.py", line 148, in execute
    result = self._query(query)
  File "C:\Users\Lenovo\AppData\Roaming\Python\Python37\site-packages\pymysql\cursors.py", line 310, in _query
    conn.query(q)
  File "C:\Users\Lenovo\AppData\Roaming\Python\Python37\site-packages\pymysql\connections.py", line 548, in query
    self._affected_rows = self._read_query_result(unbuffered=unbuffered)
  File "C:\Users\Lenovo\AppData\Roaming\Python\Python37\site-packages\pymysql\connections.py", line 775, in _read_query_result
    result.read()
  File "C:\Users\Lenovo\AppData\Roaming\Python\Python37\site-packages\pymysql\connections.py", line 1156, in read
    first_packet = self.connection._read_packet()
  File "C:\Users\Lenovo\AppData\Roaming\Python\Python37\site-packages\pymysql\connections.py", line 725, in _read_packet
    packet.raise_for_error()
  File "C:\Users\Lenovo\AppData\Roaming\Python\Python37\site-packages\pymysql\protocol.py", line 221, in raise_for_error
    err.raise_mysql_exception(self._data)
  File "C:\Users\Lenovo\AppData\Roaming\Python\Python37\site-packages\pymysql\err.py", line 143, in raise_mysql_exception
    raise errorclass(errno, errval)
pymysql.err.OperationalError: (1054, "Unknown column 'verified_type' in 'field list'")
2021-12-17 23:53:04,037 - ERROR - weibo.py[:1049] - (1366, "Incorrect string value: '\\xF0\\x9F\\x99\\x8F\\xF0\\x9F...' for column 'content' at row 1")
Traceback (most recent call last):
  File "E:/PythonProject/weibo-crawler/weibo.py", line 1045, in mysql_insert
    sql, [tuple(data.values()) for data in data_list])
  File "C:\Users\Lenovo\AppData\Roaming\Python\Python37\site-packages\pymysql\cursors.py", line 182, in executemany
    self.rowcount = sum(self.execute(query, arg) for arg in args)
  File "C:\Users\Lenovo\AppData\Roaming\Python\Python37\site-packages\pymysql\cursors.py", line 182, in <genexpr>
    self.rowcount = sum(self.execute(query, arg) for arg in args)
  File "C:\Users\Lenovo\AppData\Roaming\Python\Python37\site-packages\pymysql\cursors.py", line 148, in execute
    result = self._query(query)
  File "C:\Users\Lenovo\AppData\Roaming\Python\Python37\site-packages\pymysql\cursors.py", line 310, in _query
    conn.query(q)
  File "C:\Users\Lenovo\AppData\Roaming\Python\Python37\site-packages\pymysql\connections.py", line 548, in query
    self._affected_rows = self._read_query_result(unbuffered=unbuffered)
  File "C:\Users\Lenovo\AppData\Roaming\Python\Python37\site-packages\pymysql\connections.py", line 775, in _read_query_result
    result.read()
  File "C:\Users\Lenovo\AppData\Roaming\Python\Python37\site-packages\pymysql\connections.py", line 1156, in read
    first_packet = self.connection._read_packet()
  File "C:\Users\Lenovo\AppData\Roaming\Python\Python37\site-packages\pymysql\connections.py", line 725, in _read_packet
    packet.raise_for_error()
  File "C:\Users\Lenovo\AppData\Roaming\Python\Python37\site-packages\pymysql\protocol.py", line 221, in raise_for_error
    err.raise_mysql_exception(self._data)
  File "C:\Users\Lenovo\AppData\Roaming\Python\Python37\site-packages\pymysql\err.py", line 143, in raise_mysql_exception
    raise errorclass(errno, errval)
pymysql.err.DataError: (1366, "Incorrect string value: '\\xF0\\x9F\\x99\\x8F\\xF0\\x9F...' for column 'content' at row 1")
2021-12-17 23:53:04,471 - ERROR - weibo.py[:1049] - (1054, "Unknown column 'verified_type' in 'field list'")
Traceback (most recent call last):
  File "E:/PythonProject/weibo-crawler/weibo.py", line 1045, in mysql_insert
    sql, [tuple(data.values()) for data in data_list])
  File "C:\Users\Lenovo\AppData\Roaming\Python\Python37\site-packages\pymysql\cursors.py", line 182, in executemany
    self.rowcount = sum(self.execute(query, arg) for arg in args)
  File "C:\Users\Lenovo\AppData\Roaming\Python\Python37\site-packages\pymysql\cursors.py", line 182, in <genexpr>
    self.rowcount = sum(self.execute(query, arg) for arg in args)
  File "C:\Users\Lenovo\AppData\Roaming\Python\Python37\site-packages\pymysql\cursors.py", line 148, in execute
    result = self._query(query)
  File "C:\Users\Lenovo\AppData\Roaming\Python\Python37\site-packages\pymysql\cursors.py", line 310, in _query
    conn.query(q)
  File "C:\Users\Lenovo\AppData\Roaming\Python\Python37\site-packages\pymysql\connections.py", line 548, in query
    self._affected_rows = self._read_query_result(unbuffered=unbuffered)
  File "C:\Users\Lenovo\AppData\Roaming\Python\Python37\site-packages\pymysql\connections.py", line 775, in _read_query_result
    result.read()
  File "C:\Users\Lenovo\AppData\Roaming\Python\Python37\site-packages\pymysql\connections.py", line 1156, in read
    first_packet = self.connection._read_packet()
  File "C:\Users\Lenovo\AppData\Roaming\Python\Python37\site-packages\pymysql\connections.py", line 725, in _read_packet
    packet.raise_for_error()
  File "C:\Users\Lenovo\AppData\Roaming\Python\Python37\site-packages\pymysql\protocol.py", line 221, in raise_for_error
    err.raise_mysql_exception(self._data)
  File "C:\Users\Lenovo\AppData\Roaming\Python\Python37\site-packages\pymysql\err.py", line 143, in raise_mysql_exception
    raise errorclass(errno, errval)
pymysql.err.OperationalError: (1054, "Unknown column 'verified_type' in 'field list'")
2021-12-18 00:00:07,633 - ERROR - weibo.py[:684] - HTTPSConnectionPool(host='m.weibo.cn', port=443): Max retries exceeded with url: /detail/4675880427980609 (Caused by NewConnectionError('<urllib3.connection.HTTPSConnection object at 0x000001B2FA0E6048>: Failed to establish a new connection: [Errno 11002] getaddrinfo failed'))
Traceback (most recent call last):
  File "D:\python\lib\site-packages\urllib3\connection.py", line 160, in _new_conn
    (self._dns_host, self.port), self.timeout, **extra_kw
  File "D:\python\lib\site-packages\urllib3\util\connection.py", line 61, in create_connection
    for res in socket.getaddrinfo(host, port, family, socket.SOCK_STREAM):
  File "D:\python\lib\socket.py", line 752, in getaddrinfo
    for res in _socket.getaddrinfo(host, port, family, type, proto, flags):
socket.gaierror: [Errno 11002] getaddrinfo failed

During handling of the above exception, another exception occurred:

Traceback (most recent call last):
  File "D:\python\lib\site-packages\urllib3\connectionpool.py", line 677, in urlopen
    chunked=chunked,
  File "D:\python\lib\site-packages\urllib3\connectionpool.py", line 381, in _make_request
    self._validate_conn(conn)
  File "D:\python\lib\site-packages\urllib3\connectionpool.py", line 978, in _validate_conn
    conn.connect()
  File "D:\python\lib\site-packages\urllib3\connection.py", line 309, in connect
    conn = self._new_conn()
  File "D:\python\lib\site-packages\urllib3\connection.py", line 172, in _new_conn
    self, "Failed to establish a new connection: %s" % e
urllib3.exceptions.NewConnectionError: <urllib3.connection.HTTPSConnection object at 0x000001B2FA0E6048>: Failed to establish a new connection: [Errno 11002] getaddrinfo failed

During handling of the above exception, another exception occurred:

Traceback (most recent call last):
  File "D:\python\lib\site-packages\requests\adapters.py", line 449, in send
    timeout=timeout
  File "D:\python\lib\site-packages\urllib3\connectionpool.py", line 727, in urlopen
    method, url, error=e, _pool=self, _stacktrace=sys.exc_info()[2]
  File "D:\python\lib\site-packages\urllib3\util\retry.py", line 446, in increment
    raise MaxRetryError(_pool, url, error or ResponseError(cause))
urllib3.exceptions.MaxRetryError: HTTPSConnectionPool(host='m.weibo.cn', port=443): Max retries exceeded with url: /detail/4675880427980609 (Caused by NewConnectionError('<urllib3.connection.HTTPSConnection object at 0x000001B2FA0E6048>: Failed to establish a new connection: [Errno 11002] getaddrinfo failed'))

During handling of the above exception, another exception occurred:

Traceback (most recent call last):
  File "E:/PythonProject/weibo-crawler/weibo.py", line 665, in get_one_weibo
    retweet = self.get_long_weibo(retweet_id)
  File "E:/PythonProject/weibo-crawler/weibo.py", line 291, in get_long_weibo
    html = requests.get(url, headers=self.headers, verify=False).text
  File "D:\python\lib\site-packages\requests\api.py", line 75, in get
    return request('get', url, params=params, **kwargs)
  File "D:\python\lib\site-packages\requests\api.py", line 60, in request
    return session.request(method=method, url=url, **kwargs)
  File "D:\python\lib\site-packages\requests\sessions.py", line 533, in request
    resp = self.send(prep, **send_kwargs)
  File "D:\python\lib\site-packages\requests\sessions.py", line 646, in send
    r = adapter.send(request, **kwargs)
  File "D:\python\lib\site-packages\requests\adapters.py", line 516, in send
    raise ConnectionError(e, request=request)
requests.exceptions.ConnectionError: HTTPSConnectionPool(host='m.weibo.cn', port=443): Max retries exceeded with url: /detail/4675880427980609 (Caused by NewConnectionError('<urllib3.connection.HTTPSConnection object at 0x000001B2FA0E6048>: Failed to establish a new connection: [Errno 11002] getaddrinfo failed'))
2021-12-18 00:00:07,651 - ERROR - weibo.py[:684] - HTTPSConnectionPool(host='m.weibo.cn', port=443): Max retries exceeded with url: /detail/4675835565180134 (Caused by NewConnectionError('<urllib3.connection.HTTPSConnection object at 0x000001B2FA0E6908>: Failed to establish a new connection: [Errno 11002] getaddrinfo failed'))
Traceback (most recent call last):
  File "D:\python\lib\site-packages\urllib3\connection.py", line 160, in _new_conn
    (self._dns_host, self.port), self.timeout, **extra_kw
  File "D:\python\lib\site-packages\urllib3\util\connection.py", line 61, in create_connection
    for res in socket.getaddrinfo(host, port, family, socket.SOCK_STREAM):
  File "D:\python\lib\socket.py", line 752, in getaddrinfo
    for res in _socket.getaddrinfo(host, port, family, type, proto, flags):
socket.gaierror: [Errno 11002] getaddrinfo failed

During handling of the above exception, another exception occurred:

Traceback (most recent call last):
  File "D:\python\lib\site-packages\urllib3\connectionpool.py", line 677, in urlopen
    chunked=chunked,
  File "D:\python\lib\site-packages\urllib3\connectionpool.py", line 381, in _make_request
    self._validate_conn(conn)
  File "D:\python\lib\site-packages\urllib3\connectionpool.py", line 978, in _validate_conn
    conn.connect()
  File "D:\python\lib\site-packages\urllib3\connection.py", line 309, in connect
    conn = self._new_conn()
  File "D:\python\lib\site-packages\urllib3\connection.py", line 172, in _new_conn
    self, "Failed to establish a new connection: %s" % e
urllib3.exceptions.NewConnectionError: <urllib3.connection.HTTPSConnection object at 0x000001B2FA0E6908>: Failed to establish a new connection: [Errno 11002] getaddrinfo failed

During handling of the above exception, another exception occurred:

Traceback (most recent call last):
  File "D:\python\lib\site-packages\requests\adapters.py", line 449, in send
    timeout=timeout
  File "D:\python\lib\site-packages\urllib3\connectionpool.py", line 727, in urlopen
    method, url, error=e, _pool=self, _stacktrace=sys.exc_info()[2]
  File "D:\python\lib\site-packages\urllib3\util\retry.py", line 446, in increment
    raise MaxRetryError(_pool, url, error or ResponseError(cause))
urllib3.exceptions.MaxRetryError: HTTPSConnectionPool(host='m.weibo.cn', port=443): Max retries exceeded with url: /detail/4675835565180134 (Caused by NewConnectionError('<urllib3.connection.HTTPSConnection object at 0x000001B2FA0E6908>: Failed to establish a new connection: [Errno 11002] getaddrinfo failed'))

During handling of the above exception, another exception occurred:

Traceback (most recent call last):
  File "E:/PythonProject/weibo-crawler/weibo.py", line 665, in get_one_weibo
    retweet = self.get_long_weibo(retweet_id)
  File "E:/PythonProject/weibo-crawler/weibo.py", line 291, in get_long_weibo
    html = requests.get(url, headers=self.headers, verify=False).text
  File "D:\python\lib\site-packages\requests\api.py", line 75, in get
    return request('get', url, params=params, **kwargs)
  File "D:\python\lib\site-packages\requests\api.py", line 60, in request
    return session.request(method=method, url=url, **kwargs)
  File "D:\python\lib\site-packages\requests\sessions.py", line 533, in request
    resp = self.send(prep, **send_kwargs)
  File "D:\python\lib\site-packages\requests\sessions.py", line 646, in send
    r = adapter.send(request, **kwargs)
  File "D:\python\lib\site-packages\requests\adapters.py", line 516, in send
    raise ConnectionError(e, request=request)
requests.exceptions.ConnectionError: HTTPSConnectionPool(host='m.weibo.cn', port=443): Max retries exceeded with url: /detail/4675835565180134 (Caused by NewConnectionError('<urllib3.connection.HTTPSConnection object at 0x000001B2FA0E6908>: Failed to establish a new connection: [Errno 11002] getaddrinfo failed'))
2021-12-18 00:00:07,666 - ERROR - weibo.py[:873] - HTTPSConnectionPool(host='m.weibo.cn', port=443): Max retries exceeded with url: /api/container/getIndex?containerid=1076031337970873&page=142 (Caused by NewConnectionError('<urllib3.connection.HTTPSConnection object at 0x000001B2FA0F2F08>: Failed to establish a new connection: [Errno 11002] getaddrinfo failed'))
Traceback (most recent call last):
  File "D:\python\lib\site-packages\urllib3\connection.py", line 160, in _new_conn
    (self._dns_host, self.port), self.timeout, **extra_kw
  File "D:\python\lib\site-packages\urllib3\util\connection.py", line 61, in create_connection
    for res in socket.getaddrinfo(host, port, family, socket.SOCK_STREAM):
  File "D:\python\lib\socket.py", line 752, in getaddrinfo
    for res in _socket.getaddrinfo(host, port, family, type, proto, flags):
socket.gaierror: [Errno 11002] getaddrinfo failed

During handling of the above exception, another exception occurred:

Traceback (most recent call last):
  File "D:\python\lib\site-packages\urllib3\connectionpool.py", line 677, in urlopen
    chunked=chunked,
  File "D:\python\lib\site-packages\urllib3\connectionpool.py", line 381, in _make_request
    self._validate_conn(conn)
  File "D:\python\lib\site-packages\urllib3\connectionpool.py", line 978, in _validate_conn
    conn.connect()
  File "D:\python\lib\site-packages\urllib3\connection.py", line 309, in connect
    conn = self._new_conn()
  File "D:\python\lib\site-packages\urllib3\connection.py", line 172, in _new_conn
    self, "Failed to establish a new connection: %s" % e
urllib3.exceptions.NewConnectionError: <urllib3.connection.HTTPSConnection object at 0x000001B2FA0F2F08>: Failed to establish a new connection: [Errno 11002] getaddrinfo failed

During handling of the above exception, another exception occurred:

Traceback (most recent call last):
  File "D:\python\lib\site-packages\requests\adapters.py", line 449, in send
    timeout=timeout
  File "D:\python\lib\site-packages\urllib3\connectionpool.py", line 727, in urlopen
    method, url, error=e, _pool=self, _stacktrace=sys.exc_info()[2]
  File "D:\python\lib\site-packages\urllib3\util\retry.py", line 446, in increment
    raise MaxRetryError(_pool, url, error or ResponseError(cause))
urllib3.exceptions.MaxRetryError: HTTPSConnectionPool(host='m.weibo.cn', port=443): Max retries exceeded with url: /api/container/getIndex?containerid=1076031337970873&page=142 (Caused by NewConnectionError('<urllib3.connection.HTTPSConnection object at 0x000001B2FA0F2F08>: Failed to establish a new connection: [Errno 11002] getaddrinfo failed'))

During handling of the above exception, another exception occurred:

Traceback (most recent call last):
  File "E:/PythonProject/weibo-crawler/weibo.py", line 832, in get_one_page
    js = self.get_weibo_json(page)
  File "E:/PythonProject/weibo-crawler/weibo.py", line 183, in get_weibo_json
    js = self.get_json(params)
  File "E:/PythonProject/weibo-crawler/weibo.py", line 170, in get_json
    verify=False)
  File "D:\python\lib\site-packages\requests\api.py", line 75, in get
    return request('get', url, params=params, **kwargs)
  File "D:\python\lib\site-packages\requests\api.py", line 60, in request
    return session.request(method=method, url=url, **kwargs)
  File "D:\python\lib\site-packages\requests\sessions.py", line 533, in request
    resp = self.send(prep, **send_kwargs)
  File "D:\python\lib\site-packages\requests\sessions.py", line 646, in send
    r = adapter.send(request, **kwargs)
  File "D:\python\lib\site-packages\requests\adapters.py", line 516, in send
    raise ConnectionError(e, request=request)
requests.exceptions.ConnectionError: HTTPSConnectionPool(host='m.weibo.cn', port=443): Max retries exceeded with url: /api/container/getIndex?containerid=1076031337970873&page=142 (Caused by NewConnectionError('<urllib3.connection.HTTPSConnection object at 0x000001B2FA0F2F08>: Failed to establish a new connection: [Errno 11002] getaddrinfo failed'))
2021-12-18 00:00:07,678 - ERROR - weibo.py[:873] - HTTPSConnectionPool(host='m.weibo.cn', port=443): Max retries exceeded with url: /api/container/getIndex?containerid=1076031337970873&page=143 (Caused by NewConnectionError('<urllib3.connection.HTTPSConnection object at 0x000001B2FA0F2A88>: Failed to establish a new connection: [Errno 11002] getaddrinfo failed'))
Traceback (most recent call last):
  File "D:\python\lib\site-packages\urllib3\connection.py", line 160, in _new_conn
    (self._dns_host, self.port), self.timeout, **extra_kw
  File "D:\python\lib\site-packages\urllib3\util\connection.py", line 61, in create_connection
    for res in socket.getaddrinfo(host, port, family, socket.SOCK_STREAM):
  File "D:\python\lib\socket.py", line 752, in getaddrinfo
    for res in _socket.getaddrinfo(host, port, family, type, proto, flags):
socket.gaierror: [Errno 11002] getaddrinfo failed

During handling of the above exception, another exception occurred:

Traceback (most recent call last):
  File "D:\python\lib\site-packages\urllib3\connectionpool.py", line 677, in urlopen
    chunked=chunked,
  File "D:\python\lib\site-packages\urllib3\connectionpool.py", line 381, in _make_request
    self._validate_conn(conn)
  File "D:\python\lib\site-packages\urllib3\connectionpool.py", line 978, in _validate_conn
    conn.connect()
  File "D:\python\lib\site-packages\urllib3\connection.py", line 309, in connect
    conn = self._new_conn()
  File "D:\python\lib\site-packages\urllib3\connection.py", line 172, in _new_conn
    self, "Failed to establish a new connection: %s" % e
urllib3.exceptions.NewConnectionError: <urllib3.connection.HTTPSConnection object at 0x000001B2FA0F2A88>: Failed to establish a new connection: [Errno 11002] getaddrinfo failed

During handling of the above exception, another exception occurred:

Traceback (most recent call last):
  File "D:\python\lib\site-packages\requests\adapters.py", line 449, in send
    timeout=timeout
  File "D:\python\lib\site-packages\urllib3\connectionpool.py", line 727, in urlopen
    method, url, error=e, _pool=self, _stacktrace=sys.exc_info()[2]
  File "D:\python\lib\site-packages\urllib3\util\retry.py", line 446, in increment
    raise MaxRetryError(_pool, url, error or ResponseError(cause))
urllib3.exceptions.MaxRetryError: HTTPSConnectionPool(host='m.weibo.cn', port=443): Max retries exceeded with url: /api/container/getIndex?containerid=1076031337970873&page=143 (Caused by NewConnectionError('<urllib3.connection.HTTPSConnection object at 0x000001B2FA0F2A88>: Failed to establish a new connection: [Errno 11002] getaddrinfo failed'))

During handling of the above exception, another exception occurred:

Traceback (most recent call last):
  File "E:/PythonProject/weibo-crawler/weibo.py", line 832, in get_one_page
    js = self.get_weibo_json(page)
  File "E:/PythonProject/weibo-crawler/weibo.py", line 183, in get_weibo_json
    js = self.get_json(params)
  File "E:/PythonProject/weibo-crawler/weibo.py", line 170, in get_json
    verify=False)
  File "D:\python\lib\site-packages\requests\api.py", line 75, in get
    return request('get', url, params=params, **kwargs)
  File "D:\python\lib\site-packages\requests\api.py", line 60, in request
    return session.request(method=method, url=url, **kwargs)
  File "D:\python\lib\site-packages\requests\sessions.py", line 533, in request
    resp = self.send(prep, **send_kwargs)
  File "D:\python\lib\site-packages\requests\sessions.py", line 646, in send
    r = adapter.send(request, **kwargs)
  File "D:\python\lib\site-packages\requests\adapters.py", line 516, in send
    raise ConnectionError(e, request=request)
requests.exceptions.ConnectionError: HTTPSConnectionPool(host='m.weibo.cn', port=443): Max retries exceeded with url: /api/container/getIndex?containerid=1076031337970873&page=143 (Caused by NewConnectionError('<urllib3.connection.HTTPSConnection object at 0x000001B2FA0F2A88>: Failed to establish a new connection: [Errno 11002] getaddrinfo failed'))
2021-12-18 00:00:07,681 - ERROR - weibo.py[:873] - HTTPSConnectionPool(host='m.weibo.cn', port=443): Max retries exceeded with url: /api/container/getIndex?containerid=1076031337970873&page=144 (Caused by NewConnectionError('<urllib3.connection.HTTPSConnection object at 0x000001B2FA0F25C8>: Failed to establish a new connection: [Errno 11002] getaddrinfo failed'))
Traceback (most recent call last):
  File "D:\python\lib\site-packages\urllib3\connection.py", line 160, in _new_conn
    (self._dns_host, self.port), self.timeout, **extra_kw
  File "D:\python\lib\site-packages\urllib3\util\connection.py", line 61, in create_connection
    for res in socket.getaddrinfo(host, port, family, socket.SOCK_STREAM):
  File "D:\python\lib\socket.py", line 752, in getaddrinfo
    for res in _socket.getaddrinfo(host, port, family, type, proto, flags):
socket.gaierror: [Errno 11002] getaddrinfo failed

During handling of the above exception, another exception occurred:

Traceback (most recent call last):
  File "D:\python\lib\site-packages\urllib3\connectionpool.py", line 677, in urlopen
    chunked=chunked,
  File "D:\python\lib\site-packages\urllib3\connectionpool.py", line 381, in _make_request
    self._validate_conn(conn)
  File "D:\python\lib\site-packages\urllib3\connectionpool.py", line 978, in _validate_conn
    conn.connect()
  File "D:\python\lib\site-packages\urllib3\connection.py", line 309, in connect
    conn = self._new_conn()
  File "D:\python\lib\site-packages\urllib3\connection.py", line 172, in _new_conn
    self, "Failed to establish a new connection: %s" % e
urllib3.exceptions.NewConnectionError: <urllib3.connection.HTTPSConnection object at 0x000001B2FA0F25C8>: Failed to establish a new connection: [Errno 11002] getaddrinfo failed

During handling of the above exception, another exception occurred:

Traceback (most recent call last):
  File "D:\python\lib\site-packages\requests\adapters.py", line 449, in send
    timeout=timeout
  File "D:\python\lib\site-packages\urllib3\connectionpool.py", line 727, in urlopen
    method, url, error=e, _pool=self, _stacktrace=sys.exc_info()[2]
  File "D:\python\lib\site-packages\urllib3\util\retry.py", line 446, in increment
    raise MaxRetryError(_pool, url, error or ResponseError(cause))
urllib3.exceptions.MaxRetryError: HTTPSConnectionPool(host='m.weibo.cn', port=443): Max retries exceeded with url: /api/container/getIndex?containerid=1076031337970873&page=144 (Caused by NewConnectionError('<urllib3.connection.HTTPSConnection object at 0x000001B2FA0F25C8>: Failed to establish a new connection: [Errno 11002] getaddrinfo failed'))

During handling of the above exception, another exception occurred:

Traceback (most recent call last):
  File "E:/PythonProject/weibo-crawler/weibo.py", line 832, in get_one_page
    js = self.get_weibo_json(page)
  File "E:/PythonProject/weibo-crawler/weibo.py", line 183, in get_weibo_json
    js = self.get_json(params)
  File "E:/PythonProject/weibo-crawler/weibo.py", line 170, in get_json
    verify=False)
  File "D:\python\lib\site-packages\requests\api.py", line 75, in get
    return request('get', url, params=params, **kwargs)
  File "D:\python\lib\site-packages\requests\api.py", line 60, in request
    return session.request(method=method, url=url, **kwargs)
  File "D:\python\lib\site-packages\requests\sessions.py", line 533, in request
    resp = self.send(prep, **send_kwargs)
  File "D:\python\lib\site-packages\requests\sessions.py", line 646, in send
    r = adapter.send(request, **kwargs)
  File "D:\python\lib\site-packages\requests\adapters.py", line 516, in send
    raise ConnectionError(e, request=request)
requests.exceptions.ConnectionError: HTTPSConnectionPool(host='m.weibo.cn', port=443): Max retries exceeded with url: /api/container/getIndex?containerid=1076031337970873&page=144 (Caused by NewConnectionError('<urllib3.connection.HTTPSConnection object at 0x000001B2FA0F25C8>: Failed to establish a new connection: [Errno 11002] getaddrinfo failed'))
2021-12-18 00:00:07,694 - ERROR - weibo.py[:873] - HTTPSConnectionPool(host='m.weibo.cn', port=443): Max retries exceeded with url: /api/container/getIndex?containerid=1076031337970873&page=145 (Caused by NewConnectionError('<urllib3.connection.HTTPSConnection object at 0x000001B2FA0C9C48>: Failed to establish a new connection: [Errno 11002] getaddrinfo failed'))
Traceback (most recent call last):
  File "D:\python\lib\site-packages\urllib3\connection.py", line 160, in _new_conn
    (self._dns_host, self.port), self.timeout, **extra_kw
  File "D:\python\lib\site-packages\urllib3\util\connection.py", line 61, in create_connection
    for res in socket.getaddrinfo(host, port, family, socket.SOCK_STREAM):
  File "D:\python\lib\socket.py", line 752, in getaddrinfo
    for res in _socket.getaddrinfo(host, port, family, type, proto, flags):
socket.gaierror: [Errno 11002] getaddrinfo failed

During handling of the above exception, another exception occurred:

Traceback (most recent call last):
  File "D:\python\lib\site-packages\urllib3\connectionpool.py", line 677, in urlopen
    chunked=chunked,
  File "D:\python\lib\site-packages\urllib3\connectionpool.py", line 381, in _make_request
    self._validate_conn(conn)
  File "D:\python\lib\site-packages\urllib3\connectionpool.py", line 978, in _validate_conn
    conn.connect()
  File "D:\python\lib\site-packages\urllib3\connection.py", line 309, in connect
    conn = self._new_conn()
  File "D:\python\lib\site-packages\urllib3\connection.py", line 172, in _new_conn
    self, "Failed to establish a new connection: %s" % e
urllib3.exceptions.NewConnectionError: <urllib3.connection.HTTPSConnection object at 0x000001B2FA0C9C48>: Failed to establish a new connection: [Errno 11002] getaddrinfo failed

During handling of the above exception, another exception occurred:

Traceback (most recent call last):
  File "D:\python\lib\site-packages\requests\adapters.py", line 449, in send
    timeout=timeout
  File "D:\python\lib\site-packages\urllib3\connectionpool.py", line 727, in urlopen
    method, url, error=e, _pool=self, _stacktrace=sys.exc_info()[2]
  File "D:\python\lib\site-packages\urllib3\util\retry.py", line 446, in increment
    raise MaxRetryError(_pool, url, error or ResponseError(cause))
urllib3.exceptions.MaxRetryError: HTTPSConnectionPool(host='m.weibo.cn', port=443): Max retries exceeded with url: /api/container/getIndex?containerid=1076031337970873&page=145 (Caused by NewConnectionError('<urllib3.connection.HTTPSConnection object at 0x000001B2FA0C9C48>: Failed to establish a new connection: [Errno 11002] getaddrinfo failed'))

During handling of the above exception, another exception occurred:

Traceback (most recent call last):
  File "E:/PythonProject/weibo-crawler/weibo.py", line 832, in get_one_page
    js = self.get_weibo_json(page)
  File "E:/PythonProject/weibo-crawler/weibo.py", line 183, in get_weibo_json
    js = self.get_json(params)
  File "E:/PythonProject/weibo-crawler/weibo.py", line 170, in get_json
    verify=False)
  File "D:\python\lib\site-packages\requests\api.py", line 75, in get
    return request('get', url, params=params, **kwargs)
  File "D:\python\lib\site-packages\requests\api.py", line 60, in request
    return session.request(method=method, url=url, **kwargs)
  File "D:\python\lib\site-packages\requests\sessions.py", line 533, in request
    resp = self.send(prep, **send_kwargs)
  File "D:\python\lib\site-packages\requests\sessions.py", line 646, in send
    r = adapter.send(request, **kwargs)
  File "D:\python\lib\site-packages\requests\adapters.py", line 516, in send
    raise ConnectionError(e, request=request)
requests.exceptions.ConnectionError: HTTPSConnectionPool(host='m.weibo.cn', port=443): Max retries exceeded with url: /api/container/getIndex?containerid=1076031337970873&page=145 (Caused by NewConnectionError('<urllib3.connection.HTTPSConnection object at 0x000001B2FA0C9C48>: Failed to establish a new connection: [Errno 11002] getaddrinfo failed'))
2021-12-18 10:07:39,440 - ERROR - weibo.py[:1049] - (1366, "Incorrect string value: '\\xF0\\x9F\\x99\\x8F\\xF0\\x9F...' for column 'content' at row 1")
Traceback (most recent call last):
  File "E:/PythonProject/weibo-crawler/weibo.py", line 1045, in mysql_insert
    sql, [tuple(data.values()) for data in data_list])
  File "C:\Users\Lenovo\AppData\Roaming\Python\Python37\site-packages\pymysql\cursors.py", line 182, in executemany
    self.rowcount = sum(self.execute(query, arg) for arg in args)
  File "C:\Users\Lenovo\AppData\Roaming\Python\Python37\site-packages\pymysql\cursors.py", line 182, in <genexpr>
    self.rowcount = sum(self.execute(query, arg) for arg in args)
  File "C:\Users\Lenovo\AppData\Roaming\Python\Python37\site-packages\pymysql\cursors.py", line 148, in execute
    result = self._query(query)
  File "C:\Users\Lenovo\AppData\Roaming\Python\Python37\site-packages\pymysql\cursors.py", line 310, in _query
    conn.query(q)
  File "C:\Users\Lenovo\AppData\Roaming\Python\Python37\site-packages\pymysql\connections.py", line 548, in query
    self._affected_rows = self._read_query_result(unbuffered=unbuffered)
  File "C:\Users\Lenovo\AppData\Roaming\Python\Python37\site-packages\pymysql\connections.py", line 775, in _read_query_result
    result.read()
  File "C:\Users\Lenovo\AppData\Roaming\Python\Python37\site-packages\pymysql\connections.py", line 1156, in read
    first_packet = self.connection._read_packet()
  File "C:\Users\Lenovo\AppData\Roaming\Python\Python37\site-packages\pymysql\connections.py", line 725, in _read_packet
    packet.raise_for_error()
  File "C:\Users\Lenovo\AppData\Roaming\Python\Python37\site-packages\pymysql\protocol.py", line 221, in raise_for_error
    err.raise_mysql_exception(self._data)
  File "C:\Users\Lenovo\AppData\Roaming\Python\Python37\site-packages\pymysql\err.py", line 143, in raise_mysql_exception
    raise errorclass(errno, errval)
pymysql.err.DataError: (1366, "Incorrect string value: '\\xF0\\x9F\\x99\\x8F\\xF0\\x9F...' for column 'content' at row 1")
2021-12-18 10:08:16,105 - ERROR - weibo.py[:1049] - (1366, "Incorrect string value: '\\xF0\\x9F\\x99\\x8F\\xF0\\x9F...' for column 'content' at row 1")
Traceback (most recent call last):
  File "E:/PythonProject/weibo-crawler/weibo.py", line 1045, in mysql_insert
    sql, [tuple(data.values()) for data in data_list])
  File "C:\Users\Lenovo\AppData\Roaming\Python\Python37\site-packages\pymysql\cursors.py", line 182, in executemany
    self.rowcount = sum(self.execute(query, arg) for arg in args)
  File "C:\Users\Lenovo\AppData\Roaming\Python\Python37\site-packages\pymysql\cursors.py", line 182, in <genexpr>
    self.rowcount = sum(self.execute(query, arg) for arg in args)
  File "C:\Users\Lenovo\AppData\Roaming\Python\Python37\site-packages\pymysql\cursors.py", line 148, in execute
    result = self._query(query)
  File "C:\Users\Lenovo\AppData\Roaming\Python\Python37\site-packages\pymysql\cursors.py", line 310, in _query
    conn.query(q)
  File "C:\Users\Lenovo\AppData\Roaming\Python\Python37\site-packages\pymysql\connections.py", line 548, in query
    self._affected_rows = self._read_query_result(unbuffered=unbuffered)
  File "C:\Users\Lenovo\AppData\Roaming\Python\Python37\site-packages\pymysql\connections.py", line 775, in _read_query_result
    result.read()
  File "C:\Users\Lenovo\AppData\Roaming\Python\Python37\site-packages\pymysql\connections.py", line 1156, in read
    first_packet = self.connection._read_packet()
  File "C:\Users\Lenovo\AppData\Roaming\Python\Python37\site-packages\pymysql\connections.py", line 725, in _read_packet
    packet.raise_for_error()
  File "C:\Users\Lenovo\AppData\Roaming\Python\Python37\site-packages\pymysql\protocol.py", line 221, in raise_for_error
    err.raise_mysql_exception(self._data)
  File "C:\Users\Lenovo\AppData\Roaming\Python\Python37\site-packages\pymysql\err.py", line 143, in raise_mysql_exception
    raise errorclass(errno, errval)
pymysql.err.DataError: (1366, "Incorrect string value: '\\xF0\\x9F\\x99\\x8F\\xF0\\x9F...' for column 'content' at row 1")
2021-12-18 10:14:22,227 - ERROR - weibo.py[:1049] - (1366, "Incorrect string value: '\\xF0\\x9F\\x99\\x8F\\xF0\\x9F...' for column 'content' at row 1")
Traceback (most recent call last):
  File "E:/PythonProject/weibo-crawler/weibo.py", line 1045, in mysql_insert
    sql, [tuple(data.values()) for data in data_list])
  File "C:\Users\Lenovo\AppData\Roaming\Python\Python37\site-packages\pymysql\cursors.py", line 182, in executemany
    self.rowcount = sum(self.execute(query, arg) for arg in args)
  File "C:\Users\Lenovo\AppData\Roaming\Python\Python37\site-packages\pymysql\cursors.py", line 182, in <genexpr>
    self.rowcount = sum(self.execute(query, arg) for arg in args)
  File "C:\Users\Lenovo\AppData\Roaming\Python\Python37\site-packages\pymysql\cursors.py", line 148, in execute
    result = self._query(query)
  File "C:\Users\Lenovo\AppData\Roaming\Python\Python37\site-packages\pymysql\cursors.py", line 310, in _query
    conn.query(q)
  File "C:\Users\Lenovo\AppData\Roaming\Python\Python37\site-packages\pymysql\connections.py", line 548, in query
    self._affected_rows = self._read_query_result(unbuffered=unbuffered)
  File "C:\Users\Lenovo\AppData\Roaming\Python\Python37\site-packages\pymysql\connections.py", line 775, in _read_query_result
    result.read()
  File "C:\Users\Lenovo\AppData\Roaming\Python\Python37\site-packages\pymysql\connections.py", line 1156, in read
    first_packet = self.connection._read_packet()
  File "C:\Users\Lenovo\AppData\Roaming\Python\Python37\site-packages\pymysql\connections.py", line 725, in _read_packet
    packet.raise_for_error()
  File "C:\Users\Lenovo\AppData\Roaming\Python\Python37\site-packages\pymysql\protocol.py", line 221, in raise_for_error
    err.raise_mysql_exception(self._data)
  File "C:\Users\Lenovo\AppData\Roaming\Python\Python37\site-packages\pymysql\err.py", line 143, in raise_mysql_exception
    raise errorclass(errno, errval)
pymysql.err.DataError: (1366, "Incorrect string value: '\\xF0\\x9F\\x99\\x8F\\xF0\\x9F...' for column 'content' at row 1")
